Workbook

Sheet 清單及說明
A1: 有無料號 | B1: YETL | C1: 武器系統代號 | D1: 會計編號 | E1: 參考號獲得程度 | F1: 參考號獲得來源 | G1: 艦型 | H1: 構型報告單位 | I1: 武器級別(英) | O1: 欄位標題說明
A2: 有 | B2: YETL | C2: C35 | D2: B21317 | E2: 2 | F2: 3 | G2: FFG | H2: JSSC | I2: ARS | O2: 此顏色的標題 | P2: 此檔案其他分頁中，紅色網底為填寫的基本資料的部分(會跟其他分頁有標深藍色網底的資料同步)
A3: 無 | O3: 此顏色的標題 | P3: 此檔案其他分頁中，有標深藍色網底的整欄(1~100筆)都有下函數，跟紅色網底同步連結，所以已設定鎖定，因此不能填寫其他的值
A11: 通用
A12: *機密等級 | C12: 資料類別 | E12: *資料類型 | G12: *語言
A13: CONFIDENCIAL_LEVEL | C13: DATA_CLASS | E13: DATA_TYPE | G13: BOOK_LANGUAGE
A14: 1 | B14: 普通 | C14: 1 | D14: 技術手冊 | E14: 1 | F14: 光碟 | G14: 1 | H14: 中文
A15: 2 | B15: 密 | C15: 25 | D15: 技術命令/公報/通報 | E15: 15 | F15: 美軍技術通報 | G15: 2 | H15: 英文
A16: 3 | B16: 機密 | C16: 39 | D16: 期刊論文 | E16: 17 | F16: 發電機調速器調校方法 | G16: 3 | H16: 日文
A17: 4 | B17: 極機密 | C17: 2 | D17: 技術文件 | E17: 20 | F17: 紙本(簡體) | G17: 4 | H17: 法文
C18: 3 | D18: 技術命令/通報/公報 | E18: 22 | F18: 紙本+光碟片 | G18: 5 | H18: 荷蘭文
C19: 4 | D19: 非書資料 | E19: 23 | F19: 紙本,數位檔
C20: 5 | D20: 美軍標準作業手冊 | E20: 24 | F20: 紙本,附光碟片
C21: 6 | D21: 軍書 | E21: 25 | F21: 表格
C22: 7 | D22: 海軍艦艇技術手冊 | E22: 26 | F22: 技術命令
C23: 8 | D23: 航空技令 | E23: 27 | F23: 磁片
C24: 9 | D24: 採購合約 | E24: 30 | F24: 紙本+數位檔
C25: 10 | D25: 規範 | E25: 35 | F25: 紙本,附磁片
C26: 11 | D26: 報告 | E26: 36 | F26: 技術通報
C27: 12 | D27: 期刊/論文 | E27: 39 | F27: 光碟+數位
C28: 13 | D28: 準則 | E28: 40 | F28: 後錨機汽油引擎換用GM-671引擎
C29: 14 | D29: 裝備手冊 | E29: 41 | F29: 技術公報
C30: 15 | D30: 圖書 | E30: 2 | F30: 數位
... C32: 17 | D32: 標準程序書 | E32: 4 | F32: 幻燈片
E33: 5 | F33: 相片
E34: 6 | F34: 錄音帶
E35: 7 | F35: 錄影帶
E36: 8 | F36: 紙本+光碟
E37: 9 | F37: 紙本+微軟
E38: 10 | F38: 紙本+磁片
E39: 11 | F39: 紙本+數位
E40: 12 | F40: 影印本
E41: 13 | F41: 紙本
A47: 書籍
A48: *異動方式 | C48: 艦型/艦艇別 | E48: 後勤文件類別 | G48: *儲放室
A49: MODIFY_TYPE | C49: PROJECT_NAME | E49: DOC_CLASS | G49: STORE_ROOM
A50: N | B50: 新增 | C50: 001 | D50: 通用 | E50: 1 | F50: 補給類 | G50: 1 | H50: 光一室
A51: C | B51: 修改 | C51: 002 | D51: 500MD | E51: 10 | F51: 控制 | G51: 2 | H51: 光二室
A52: D | B52: 刪除 | C52: 003 | D52: E-2T | E52: 11 | F52: 參考資料 | G52: 3 | H52: 軍書室
C53: 004 | D53: FAB(飛彈快艇) | E53: 12 | F53: 聲納 | G53: 4 | H53: 專案室
...

Sheet 基本資料填寫
A1: 輔助列 | B1: 有無料號 | C1: 總 | D1: 18 | E1: 全 | F1: 是否總 | G1: 是否18 | H1: 是否全 | I1: 項次 | J1: ITEM NO PLSIN | K1: 料單狀態 | L1: 表單編號 | M1: 適用裝備 名稱 | N1: 族群結構碼 | O1: 配件號碼(P/N) | P1: 廠商英文品名 | Q1: 中文品名 | R1: 中文品名(9字內) | S1: 統一組類別 | T1: YETL | U1: 品項識別碼(後五碼) | V1: 品項識別碼 | W1: NSN | X1: 裝置數 | Y1: 全艦裝置數 | Z1: 撥發單位 | AA1: 美金單價 | AB1: 交貨時間 | AC1: 每百萬小時預估故障次數 | AD1: 平均故障間隔(MTBF) (小時) | AE1: 平均修護時間(MTTR) (小時) | AF1: 是否為 可修件 (Y/N) | AH1: 裝備代號 | AI1: 裝備序號 | AJ1: 構型報告單位 | AK1: 武器級別(英) | AL1: 裝備維修等級代碼 | AN1: INC英文品名 | AO1: 品名代號 | AP1: FIIG | AQ1: 文件來源 | AR1: 代理商 | AS1: 規格資料(1) 縮寫 | AT1: 規格資料(1) 英文 | AU1: 規格資料(1)翻譯 | AV1: 英答(1) | AW1: 中答(1) | AX1: 規格資料(2) 縮寫 | AY1: 規格資料(2) 英文 | AZ1: 規格資料(2)翻譯 | BA1: 英答(2) | BB1: 中答(2) | BC1: 規格資料(3)縮寫 | BD1: 規格資料(3) 英文 | BE1: 規格資料(3) 翻譯 | BF1: 英答(3) | BG1: 中答(3) | BH1: 規格資料(4) 縮寫 | BI1: 規格資料(4) 英文 | BJ1: 規格資料(4) 翻譯 | BK1: 英答(4) | BL1: 中答(4) | BM1: 規格資料(5)縮寫 | BN1: 規格資料(5) 英文 | BO1: 規格資料(5) 翻譯 | BP1: 英答(5) | BQ1: 中答(5) | BR1: 圖片路徑 | BS1: 檔別區分 | BT1: 專案代號 | BU1: 重量(KG) | BW1: 武器系統代號 | BX1: 會計編號 | BY1: 單位包裝量 | BZ1: 存儲壽限代號 | CA1: 檔別代號 | CB1: 機密性代號 | CC1: 消耗性代號 | CD1: 規格指示 | CE1: 海軍軍品來源 | CF1: 儲存型式 | CG1: 壽限處理代號 | CH1: 製造能量 | CI1: 修理能量 | CJ1: 廠商來源代號 | CK1: 廠家登記代號 | CL1: 備註_廠商代號 | CM1: 廠家製造商 | CN1: P/N獲得 程度 | CO1: P/N獲得來源 | CP1: CID/NO. | CQ1: 艦型 | CR1: 型式 | CS1: 品名 | CT1: 位置 | CU1: 上一層裝備(中) | CV1: 上一層裝備(英) | CW1: 上層適用裝備單機識別碼CID | CY1: 圖名/書名 | CZ1: 專案文件管制碼(免填) | DA1: 會計編號 | DB1: ESWBS(五碼) | DC1: 階段代號(免填) | DD1: 文件管制碼：_文件類別-單位別(免填) | DE1: 文件管制碼：_文件類別-文件分類(免填) | DF1: 文件管制碼：_流水號(第一碼)(免填) | DG1: 文件管制碼：_流水號(第二碼)(免填) | DH1: 文件管制碼：_流水號(第三碼)(免填) | DI1: 流水號(第四~六碼)(免填) | DJ1: 文件管制碼：_流水號(第七碼)(免填) | DK1: 文件管制碼：專案代號(免填) | DL1: 技術文件版別 | DM1: 船廠圖號 | DN1: 設計圖號 | DO1: 階段代號(免填) | DP1: 機密等級 | DQ1: 資料類別 | DR1: 資料類型 | DS1: 語言 | DU1: 系統功能名稱(中+英) (族群結構碼上的名稱)
A2: =IF(B2="","",B2&"-"&COUNTIF($B$2:B2,B2)) | C2: =IF(F2="","",F2&"-"&COUNTIF(F$2:$H2,F2)) -> 總-1 | D2: =IF(G2="","",G2&"-"&COUNTIF(G$2:$H2,G2)) | E2: =IF(H2="","",H2&"-"&COUNTIF($H$2:H2,H2)) -> 全-1 | F2: 總 | H2: 全 | I2: =IF(Q2="","",COUNTA($Q$2:Q2)) -> 1 | J2: 0000 | K2: 繳交成功 | L2: A0009 | M2: 聲力電話系統 | N2: 43212 | O2: TA-4CI | P2: Acoustic Telephone System | Q2: 聲力電話系統 | R2: 聲力電話系統 | S2: 5805 | T2: YETL | U2: 22090 | V2: =T2&U2 -> YETL22090 | W2: =IF(S2="","",S2&V2) -> 5805YETL22090 | X2: 1 | Y2: 1 | Z2: EA | AA2: 530000 | AB2: 3 M | AC2: 83.3 | AD2: 12000 | AE2: 1.5 | AF2: Y | AH2: 3 | AI2: 0823 | AJ2: JSSC | AK2: ARS | AL2: O | AN2: TELEPHONE SYSTEM | AO2: 35522 | AP2: A23800 | AQ2: 聲力電話系統技術手冊 | AR2: 堃翊工程有限公司 | AS2: CLQL | AT2: COLLOQUIAL NAME | AU2: 口語名稱 | AV2: Acoustic Telephone System | AW2: 聲力電話系統 | AX2: AYDS | AY2: END ITEM NAME | AZ2: 最終裝備名稱 | BA2: 43212 Acoustic Telephone System | BB2: 43212 聲力電話系統 | BC2: AJKC | BD2: SUPPLY ITEMS AND QUANTITIES | BE2: 供應項目和數量 | BG2: 至少10項：12/24站壁掛式聲力電話、12/24站埋入式聲力電話、埋入式電話插座、壁掛式電話插座、警示燈、電話放置箱、繼電器控制盒等。 | BR2: C:\\SynologyDrive\\01 JSSC專案\\12 料號申編\\06 次要裝備\\50 聲力電話\\圖片\\01_聲力電話系統.jpg | BS2: C | BT2: 4 | BW2: C35 | BX2: B21317 | BY2: 1 | BZ2: 0 | CA2: E | CB2: U | CC2: M | CD2: E | CE2: C | CF2: A | CG2: 00 | CH2: E | CI2: 0 | CJ2: A | CK2: 1973B | CL2: =IF(CK2="","",CJ2&CK2) -> A1973B | CM2: SCM SISTEMAS,S.L. | CN2: 2 | CO2: 3 | CP2: 27NYE0823 | CQ2: FFG | CR2: TA-4CI | CS2: 聲力電話系統 | CT2: 前/後機艙 | CY2: 聲力電話系統技術手冊 | CZ2: =IF(DB2="","",DB2&"-"&DC2&"-"&DD2&DE2&"-"&DF2&DG2&"-"&DH2&"-"&DI2&DJ2&"-"&DK2) -> 43212------ | DA2: =IF(CY2="","",BX2) -> B21317 | DB2: 43212 | DL2: 0 | DM2: EK432121 | DN2: EN432121 | DP2: 1 | DQ2: 1 | DR2: 2 | DS2: 1 | DU2: =IF(M2=0,"",Q2&P2) -> 聲力電話系統Acoustic Telephone System
A3: =IF(B3="","",B3&"-"&COUNTIF($B$2:B3,B3)) | C3: =IF(F3="","",F3&"-"&COUNTIF(F$2:$H3,F3)) | D3: =IF(G3="","",G3&"-"&COUNTIF(G$2:$H3,G3)) -> 18-1 | E3: =IF(H3="","",H3&"-"&COUNTIF($H$2:H3,H3)) -> 全-2 | G3: 18 | H3: 全 | I3: =IF(Q3="","",COUNTA($Q$2:Q3)) -> 2 | J3: 0001 | K3: 繳交成功 | L3: A0010 | M3: 聲力電話系統 | N3: 432121 | O3: 455.029.4.21H | P3: Sound Powered Telephone, 12 Stations, Wall-Mounted (with H27A Jack) | Q3: 12站壁掛式聲力電話(附H27A 插座) | R3: 12站壁掛式聲力電話 | S3: 5805 | T3: YETL | U3: 22088 | V3: =T3&U3 -> YETL22088 | W3: =IF(S3="","",S3&V3) -> 5805YETL22088 | X3: 1 | Y3: 23 | Z3: EA | AA3: 1200 | AB3: 3 M | AC3: 83.3 | AD3: 12000 | AE3: 1.5 | AF3: Y | AH3: 4 | AI3: 0823 | AJ3: JSSC | AK3: ARS | AL3: 0 | AN3: TELEPHONE SET | AO3: 00307 | AP3: T187-D | AQ3: 聲力電話系統技術手冊 | AR3: 堃翊工程有限公司 | AS3: CLQL | AT3: COLLOQUIAL NAME | AU3: 口語名稱 | AV3: Sound Powered Telephone, 12 Stations, Wall-Mounted (with H27A Jack) | AW3: 12站壁掛式聲力電話(附H27A 插座) | AX3: ANPX | AY3: TRANSMITTER CURRENT SUPPLY SOURCE | AZ3: 傳送器電流供應來源 | BA3: SOUND POWERED | BB3: 聲力供電 | BC3: STYL | BD3: STYLE DESIGNATOR | BE3: 外觀型式識別碼 | BF3: MANUAL CRANK OPERATED | BG3: 手動搖柄操作 | BH3: ABMK | BI3: OVERALL WIDTH | BJ3: 總寬度 | BK3: 160 mm | BL3: 160毫米 | BM3: ABHP | BN3: OVERALL LENGTH | BO3: 總長度 | BP3: 260 mm | BQ3: 260毫米 | BR3: C:\\SynologyDrive\\01 JSSC專案\\12 料號申編\\06 次要裝備\\50 聲力電話\\圖片\\02.12站壁掛式聲力電話.jpg | BS3: C | BT3: 4 | BW3: C35 | BX3: B21317 | BY3: 1 | BZ3: 0 | CA3: C | CB3: U | CC3: M | CD3: E | CE3: C | CF3: A | CG3: 00 | CH3: E | CI3: 0 | CJ3: A | CK3: 1973B | CL3: =IF(CK3="","",CJ3&CK3) -> A1973B | CM3: SCM SISTEMAS,S.L. | CN3: 2 | CO3: 3 | CP3: 27NYE0823 | CQ3: FFG | CR3: TA-4CI | CS3: 聲力電話系統 | CT3: 前/後機艙 | CU3: 聲力電話系統 | CV3: Acoustic Telephone System | CW3: 27NYE0823 | CZ3: =IF(DB3="","",DB3&"-"&DC3&"-"&DD3&DE3&"-"&DF3&DG3&"-"&DH3&"-"&DI3&DJ3&"-"&DK3) | DA3: =IF(CY3="","",BX3)
A4: =IF(B4="","",B4&"-"&COUNTIF($B$2:B4,B4)) | C4: =IF(F4="","",F4&"-"&COUNTIF(F$2:$H4,F4)) | D4: =IF(G4="","",G4&"-"&COUNTIF(G$2:$H4,G4)) -> 18-2 | E4: =IF(H4="","",H4&"-"&COUNTIF($H$2:H4,H4)) -> 全-3 | G4: 18 | H4: 全 | I4: =IF(Q4="","",COUNTA($Q$2:Q4)) -> 3 | J4: 0002 | K4: 繳交成功 | L4: A0011 | M4: 聲力電話系統 | N4: 432122 | O4: 455.031.4.16H | P4: Sound Powered Telephone, 24 Stations, Wall-Mounted (with H27A Jack) | Q4: 24站壁掛式聲力電話(附H27A 插座) | R4: 24站壁掛式聲力電話 | S4: 5805 | T4: YETL | U4: 22087 | V4: =T4&U4 -> YETL22087 | W4: =IF(S4="","",S4&V4) -> 5805YETL22087 | X4: 1 | Y4: 62 | Z4: EA | AA4: 1200 | AB4: 3 M | AC4: 83.3 | AD4: 12000 | AE4: 1.5 | AF4: Y | AH4: 4 | AI4: 0823 | AJ4: JSSC | AK4: ARS | AL4: 0 | AN4: TELEPHONE SET | AO4: 00307 | AP4: T187-D | AQ4: 聲力電話系統技術手冊 | AR4: 堃翊工程有限公司 | AS4: CLQL | AT4: COLLOQUIAL NAME | AU4: 口語名稱 | AV4: Sound Powered Telephone, 24 Stations, Wall-Mounted (with H27A Jack) | AW4: 24站壁掛式聲力電話(附H27A 插座) | AX4: ANPX | AY4: TRANSMITTER CURRENT SUPPLY SOURCE | AZ4: 傳送器電流供應來源 | BA4: SOUND POWERED | BB4: 聲力供電 | BC4: STYL | BD4: STYLE DESIGNATOR | BE4: 外觀型式識別碼 | BF4: MANUAL CRANK OPERATED | BG4: 手動搖柄操作 | BH4: ABMK | BI4: OVERALL WIDTH | BJ4: 總寬度 | BK4: 160 mm | BL4: 160毫米 | BM4: ABHP | BN4: OVERALL LENGTH | BO4: 總長度 | BP4: 260 mm | BQ4: 260毫米 | BR4: C:\\SynologyDrive\\01 JSSC專案\\12 料號申編\\06 次要裝備\\50 聲力電話\\圖片\\03.24站壁掛式聲力電話.jpg | BS4: C | BT4: 4 | BW4: C35 | BX4: B21317 | BY4: 1 | BZ4: 0 | CA4: C | CB4: U | CC4: M | CD4: E | CE4: C | CF4: A | CG4: 00 | CH4: E | CI4: 0 | CJ4: A | CK4: 1973B | CL4: =IF(CK4="","",CJ4&CK4) -> A1973B | CM4: SCM SISTEMAS,S.L. | CN4: 2 | CO4: 3 | CP4: 27NYE0823 | CQ4: FFG | CR4: TA-4CI | CS4: 聲力電話系統 | CT4: 前/後機艙 | CU4: 聲力電話系統 | CV4: Acoustic Telephone System | CW4: 27NYE0823 | CZ4: =IF(DB4="","",DB4&"-"&DC4&"-"&DD4&DE4&"-"&DF4&DG4&"-"&DH4&"-"&DI4&DJ4&"-"&DK4) | DA4: =IF(CY4="","",BX4)
A5: =IF(B5="","",B5&"-"&COUNTIF($B$2:B5,B5)) | C5: =IF(F5="","",F5&"-"&COUNTIF(F$2:$H5,F5)) | D5: =IF(G5="","",G5&"-"&COUNTIF(G$2:$H5,G5)) -> 18-3 | E5: =IF(H5="","",H5&"-"&COUNTIF($H$2:H5,H5)) -> 全-4 | G5: 18 | H5: 全 | I5: =IF(Q5="","",COUNTA($Q$2:Q5)) -> 4 | J5: 0003 | K5: 繳交成功 | L5: A0012 | M5: 聲力電話系統 | N5: 432123 | O5: 455.005.7H | P5: Sound Powered Telephone (12-station/built-in with dimmer and H27A jack) | Q5: 12站埋入式聲力電話(附H27A 插座) | R5: 12站埋入式聲力電話 | S5: 5805 | T5: YETL | U5: 22086 | V5: =T5&U5 -> YETL22086 | W5: =IF(S5="","",S5&V5) -> 5805YETL22086 | X5: 1 | Y5: 7 | Z5: EA | AA5: 1200 | AB5: 3 M | AC5: 83.3 | AD5: 12000 | AE5: 1.5 | AF5: Y | AH5: 4 | AI5: 0823 | AJ5: JSSC | AK5: ARS | AL5: 0 | AN5: TELEPHONE SET | AO5: 00307 | AP5: T187-D | AQ5: 聲力電話系統技術手冊 | AR5: 堃翊工程有限公司 | AS5: CLQL | AT5: COLLOQUIAL NAME | AU5: 口語名稱 | AV5: Sound Powered Telephone (12-station/built-in with dimmer and H27A jack) | AW5: 12站埋入式聲力電話(附H27A 插座) | AX5: ANPX | AY5: TRANSMITTER CURRENT SUPPLY SOURCE | AZ5: 傳送器電流供應來源 | BA5: SOUND POWERED | BB5: 聲力供電 | BC5: STYL | BD5: STYLE DESIGNATOR | BE5: 外觀型式識別碼 | BF5: MANUAL CRANK OPERATED | BG5: 手動搖柄操作 | BH5: ABMK | BI5: OVERALL WIDTH | BJ5: 總寬度 | BK5: 160 mm | BL5: 160毫米 | BM5: ABHP | BN5: OVERALL LENGTH | BO5: 總長度 | BP5: 200 mm | BQ5: 200 毫米 | BR5: C:\\SynologyDrive\\01 JSSC專案\\12 料號申編\\06 次要裝備\\50 聲力電話\\圖片\\04.12站埋入式聲力電話.jpg | BS5: C | BT5: 4 | BW5: C35 | BX5: B21317 | BY5: 1 | BZ5: 0 | CA5: C | CB5: U | CC5: M | CD5: E | CE5: C | CF5: A | CG5: 00 | CH5: E | CI5: 0 | CJ5: A | CK5: 1973B | CL5: =IF(CK5="","",CJ5&CK5) -> A1973B | CM5: SCM SISTEMAS,S.L. | CN5: 2 | CO5: 3 | CP5: 27NYE0823 | CQ5: FFG | CR5: TA-4CI | CS5: 聲力電話系統 | CT5: 前/後機艙 | CU5: 聲力電話系統 | CV5: Acoustic Telephone System | CW5: 27NYE0823 | CZ5: =IF(DB5="","",DB5&"-"&DC5&"-"&DD5&DE5&"-"&DF5&DG5&"-"&DH5&"-"&DI5&DJ5&"-"&DK5) | DA5: =IF(CY5="","",BX5)
A6: =IF(B6="","",B6&"-"&COUNTIF($B$2:B6,B6)) | C6: =IF(F6="","",F6&"-"&COUNTIF(F$2:$H6,F6)) | D6: =IF(G6="","",G6&"-"&COUNTIF(G$2:$H6,G6)) -> 18-4 | E6: =IF(H6="","",H6&"-"&COUNTIF($H$2:H6,H6)) -> 全-5 | G6: 18 | H6: 全 | I6: =IF(Q6="","",COUNTA($Q$2:Q6)) -> 5 | J6: 0004 | K6: 繳交成功 | L6: A0013 | M6: 聲力電話系統 | N6: 432124 | O6: 455.029.4.12H | P6: Sound Powered Telephone (24-station/built-in with dimmer and H27A jack) | Q6: 24站埋入式聲力電話(附H27A 插座) | R6: 24站埋入式聲力電話 | S6: 5805 | T6: YETL | U6: 22085 | V6: =T6&U6 -> YETL22085 | W6: =IF(S6="","",S6&V6) -> 5805YETL22085 | X6: 1 | Y6: 5 | Z6: EA | AA6: 1200 | AB6: 3 M | AC6: 83.3 | AD6: 12000 | AE6: 1.5 | AF6: Y | AH6: 4 | AI6: 0823 | AJ6: JSSC | AK6: ARS | AL6: 0 | AN6: TELEPHONE SET | AO6: 00307 | AP6: T187-D | AQ6: 聲力電話系統技術手冊 | AR6: 堃翊工程有限公司 | AS6: CLQL | AT6: COLLOQUIAL NAME | AU6: 口語名稱 | AV6: Sound Powered Telephone (24-station/built-in with dimmer and H27A jack) | AW6: 24站埋入式聲力電話(附H27A 插座) | AX6: ANPX | AY6: TRANSMITTER CURRENT SUPPLY SOURCE | AZ6: 傳送器電流供應來源 | BA6: SOUND POWERED | BB6: 聲力供電 | BC6: STYL | BD6: STYLE DESIGNATOR | BE6: 外觀型式識別碼 | BF6: MANUAL CRANK OPERATED | BG6: 手動搖柄操作 | BH6: ABMK | BI6: OVERALL WIDTH | BJ6: 總寬度 | BK6: 160 mm | BL6: 160毫米 | BM6: ABHP | BN6: OVERALL LENGTH | BO6: 總長度 | BP6: 200 mm | BQ6: 200 毫米 | BR6: C:\\SynologyDrive\\01 JSSC專案\\12 料號申編\\06 次要裝備\\50 聲力電話\\圖片\\05.24站埋入式聲力電話.jpg | BS6: C | BT6: 4 | BW6: C35 | BX6: B21317 | BY6: 1 | BZ6: 0 | CA6: C | CB6: U | CC6: M | CD6: E | CE6: C | CF6: A | CG6: 00 | CH6: E | CI6: 0 | CJ6: A | CK6: 1973B | CL6: =IF(CK6="","",CJ6&CK6) -> A1973B | CM6: SCM SISTEMAS,S.L. | CN6: 2 | CO6: 3 | CP6: 27NYE0823 | CQ6: FFG | CR6: TA-4CI | CS6: 聲力電話系統 | CT6: 前/後機艙 | CU6: 聲力電話系統 | CV6: Acoustic Telephone System | CW6: 27NYE0823 | CZ6: =IF(DB6="","",DB6&"-"&DC6&"-"&DD6&DE6&"-"&DF6&DG6&"-"&DH6&"-"&DI6&DJ6&"-"&DK6) | DA6: =IF(CY6="","",BX6)
A7: =IF(B7="","",B7&"-"&COUNTIF($B$2:B7,B7)) -> 無-1 | B7: 無 | C7: =IF(F7="","",F7&"-"&COUNTIF(F$2:$H7,F7)) | D7: =IF(G7="","",G7&"-"&COUNTIF(G$2:$H7,G7)) -> 18-5 | E7: =IF(H7="","",H7&"-"&COUNTIF($H$2:H7,H7)) -> 全-6 | G7: 18 | H7: 全 | I7: =IF(Q7="","",COUNTA($Q$2:Q7)) -> 6 | J7: 0005 | K7: 待送出 | L7: A0073 | M7: 聲力電話系統 | N7: 432125 | O7: 350.500 | P7: Portable chest head sound powered telephone (with/without foot switch) | Q7: 頭戴式聲力電話(頭戴型及腳控型) | R7: 頭戴式聲力電話 | S7: 5965 | T7: YETL | U7: 申請中 | V7: =T7&U7 -> YETL申請中 | W7: =IF(S7="","",S7&V7) -> 5965YETL申請中 | X7: 1 | Y7: 89 | Z7: EA | AA7: 1200 | AB7: 3 M | AC7: 100 | AD7: 10000 | AE7: 1 | AF7: Y | AH7: 4 | AI7: 0823 | AJ7: JSSC | AK7: ARS | AL7: 0 | AN7: HEADSET-CHEST SET,ELECTRICAL | AO7: 00710 | AP7: A545Q0 | AQ7: 聲力電話系統技術手冊 | AR7: 堃翊工程有限公司 | AS7: CLQL | AT7: COLLOQUIAL NAME | AU7: 口語名稱 | AV7: Portable chest head sound powered telephone (with/without foot switch) | AW7: 頭戴式聲力電話(頭戴型及腳控型) | AX7: AHES | AY7: EARPHONE QUANTITY | AZ7: 耳機數量 | BA7: 2 | BB7: 2，左右耳 | BC7: CBBL | BD7: FEATURES PROVIDED | BE7: 提供的附加功能 | BF7: FOOT SWITCH (TA-PC-FS only) | BG7: 腳控發話功能（僅限 TA-PC-FS） | BR7: C:\\SynologyDrive\\01 JSSC專案\\12 料號申編\\06 次要裝備\\50 聲力電話\\圖片\\06.頭戴式.jpg | BS7: C | BT7: 4 | BU7: 1.5-1.8 | BW7: C35 | BX7: B21317 | BY7: 1 | BZ7: 0 | CA7: C | CB7: U | CC7: M | CD7: E | CE7: C | CF7: A | CG7: 00 | CH7: E | CI7: 0 | CJ7: A | CK7: 1973B | CL7: =IF(CK7="","",CJ7&CK7) -> A1973B | CM7: SCM SISTEMAS,S.L. | CN7: 2 | CO7: 3 | CP7: 27NYE0823 | CQ7: FFG | CR7: TA-4CI | CS7: 聲力電話系統 | CT7: 前/後機艙 | CU7: 聲力電話系統 | CV7: Acoustic Telephone System | CW7: 27NYE0823 | CZ7: =IF(DB7="","",DB7&"-"&DC7&"-"&DD7&DE7&"-"&DF7&DG7&"-"&DH7&"-"&DI7&DJ7&"-"&DK7) | DA7: =IF(CY7="","",BX7)
A8: =IF(B8="","",B8&"-"&COUNTIF($B$2:B8,B8)) | C8: =IF(F8="","",F8&"-"&COUNTIF(F$2:$H8,F8)) | D8: =IF(G8="","",G8&"-"&COUNTIF(G$2:$H8,G8)) -> 18-6 | E8: =IF(H8="","",H8&"-"&COUNTIF($H$2:H8,H8)) -> 全-7 | G8: 18 | H8: 全 | I8: =IF(Q8="","",COUNTA($Q$2:Q8)) -> 7 | J8: 0006 | K8: 繳交成功 | L8: A0014 | M8: 聲力電話系統 | N8: 432126 | O8: 149.015 SCM | P8: Panel-mounted jack | Q8: 聲力電話插座 (埋入式) | R8: 聲力電話插座/埋入 | S8: 5935 | T8: YETL | U8: 22089 | V8: =T8&U8 -> YETL22089 | W8: =IF(S8="","",S8&V8) -> 5935YETL22089 | X8: 1 | Y8: 108 | Z8: EA | AA8: 120 | AB8: 3 M | AC8: 66.7 | AD8: 15000 | AE8: 0.5 | AF8: Y | AH8: 4 | AI8: 0823 | AJ8: JSSC | AK8: ARS | AL8: 0 | AN8: JACK BOX | AO8: 16136 | AP8: A17600 | AQ8: 聲力電話系統技術手冊 | AR8: 堃翊工程有限公司 | AS8: CLQL | AT8: COLLOQUIAL NAME | AU8: 口語名稱 | AV8: Panel-mounted jack | AW8: 聲力電話插座 (埋入式) | AX8: STYL | AY8: STYLE DESIGNATOR | AZ8: 外觀型式 | BA8: SQUARE, FLUSH MOUNTING | BB8: 方形面板，嵌入式安裝 | BC8: MATT | BD8: MATERIAL | BE8: 材質 | BF8: Brass,Stainless Steel | BG8: 黃銅,不鏽鋼 | BH8: ABMK | BI8: OVERALL WIDTH | BJ8: 總寬度 | BK8: 31.8 mm | BL8: 31.8毫米(左右) | BM8: ABHP | BN8: OVERALL LENGTH | BO8: 總長度 | BP8: 31.8 mm | BQ8: 31.8毫米(前後) | BR8: C:\\SynologyDrive\\01 JSSC專案\\12 料號申編\\06 次要裝備\\50 聲力電話\\圖片\\07.聲力電話插座 (埋入式).jpg | BS8: C | BT8: 4 | BW8: C35 | BX8: B21317 | BY8: 1 | BZ8: 0 | CA8: C | CB8: U | CC8: M | CD8: E | CE8: C | CF8: A | CG8: 00 | CH8: E | CI8: 0 | CJ8: A | CK8: 1973B | CL8: =IF(CK8="","",CJ8&CK8) -> A1973B | CM8: SCM SISTEMAS,S.L. | CN8: 2 | CO8: 3 | CP8: 27NYE0823 | CQ8: FFG | CR8: TA-4CI | CS8: 聲力電話系統 | CT8: 前/後機艙 | CU8: 聲力電話系統 | CV8: Acoustic Telephone System | CW8: 27NYE0823 | CZ8: =IF(DB8="","",DB8&"-"&DC8&"-"&DD8&DE8&"-"&DF8&DG8&"-"&DH8&"-"&DI8&DJ8&"-"&DK8) | DA8: =IF(CY8="","",BX8)
A9: =IF(B9="","",B9&"-"&COUNTIF($B$2:B9,B9)) | C9: =IF(F9="","",F9&"-"&COUNTIF(F$2:$H9,F9)) | D9: =IF(G9="","",G9&"-"&COUNTIF(G$2:$H9,G9)) -> 18-7 | E9: =IF(H9="","",H9&"-"&COUNTIF($H$2:H9,H9)) -> 全-8 | G9: 18 | H9: 全 | I9: =IF(Q9="","",COUNTA($Q$2:Q9)) -> 8 | J9: 0007 | K9: 繳交成功 | L9: A0015 | M9: 聲力電話系統 | N9: 432127 | O9: 350.501 SCM | P9: Jack-box for connection | Q9: 聲力電話插座 (防水壁掛式) | R9: 聲力電話插座/壁掛 | S9: 5935 | T9: YETL | U9: 22119 | V9: =T9&U9 -> YETL22119 | W9: =IF(S9="","",S9&V9) -> 5935YETL22119 | X9: 1 | Y9: 116 | Z9: EA | AA9: 120 | AB9: 3 M | AC9: 71.4 | AD9: 14000 | AE9: 0.5 | AF9: Y | AH9: 4 | AI9: 0823 | AJ9: JSSC | AK9: ARS | AL9: 0 | AN9: JACK BOX | AO9: 16136 | AP9: A17600 | AQ9: 聲力電話系統技術手冊 | AR9: 堃翊工程有限公司 | AS9: CLQL | AT9: COLLOQUIAL NAME | AU9: 口語名稱 | AV9: Jack-box for connection | AW9: 聲力電話插座 (防水壁掛式) | AX9: STYL | AY9: STYLE DESIGNATOR | AZ9: 外觀型式 | BA9: ROUND, SURFACE MOUNTING | BB9: 圓形壁掛式 | BC9: MATT | BD9: MATERIAL | BE9: 材質 | BF9: Made of brass | BG9: 黃銅製防水盒 | BH9: ABMK | BI9: OVERALL WIDTH | BJ9: 總寬度 | BK9: 103 mm | BL9: 103 毫米(左右) | BM9: ABFY | BN9: OVERALL DEPTH | BO9: 總深度 | BP9: 70 mm | BQ9: 70毫米(前後) | BR9: C:\\SynologyDrive\\01 JSSC專案\\12 料號申編\\06 次要裝備\\50 聲力電話\\圖片\\08.聲力電話插座(壁掛).png | BS9: C | BT9: 4 | BW9: C35 | BX9: B21317 | BY9: 1 | BZ9: 0 | CA9: C | CB9: U | CC9: M | CD9: E | CE9: C | CF9: A | CG9: 00 | CH9: E | CI9: 0 | CJ9: A | CK9: 1973B | CL9: =IF(CK9="","",CJ9&CK9) -> A1973B | CM9: SCM SISTEMAS,S.L. | CN9: 2 | CO9: 3 | CP9: 27NYE0823 | CQ9: FFG | CR9: TA-4CI | CS9: 聲力電話系統 | CT9: 前/後機艙 | CU9: 聲力電話系統 | CV9: Acoustic Telephone System | CW9: 27NYE0823 | CZ9: =IF(DB9="","",DB9&"-"&DC9&"-"&DD9&DE9&"-"&DF9&DG9&"-"&DH9&"-"&DI9&DJ9&"-"&DK9) | DA9: =IF(CY9="","",BX9)
A10: =IF(B10="","",B10&"-"&COUNTIF($B$2:B10,B10)) -> 無-2 | B10: 無 | C10: =IF(F10="","",F10&"-"&COUNTIF(F$2:$H10,F10)) | D10: =IF(G10="","",G10&"-"&COUNTIF(G$2:$H10,G10)) -> 18-8 | E10: =IF(H10="","",H10&"-"&COUNTIF($H$2:H10,H10)) -> 全-9 | G10: 18 | H10: 全 | I10: =IF(Q10="","",COUNTA($Q$2:Q10)) -> 9 | J10: 0008 | K10: 待送出 | L10: A0074 | M10: 聲力電話系統 | N10: 432128 | O10: 455.805 | P10: Audio Frecuency Amplifie | Q10: 聲力電話放大器 | R10: 聲力電話放大器 | S10: 5965 | T10: YETL | U10: 申請中 | V10: =T10&U10 -> YETL申請中 | W10: =IF(S10="","",S10&V10) -> 5965YETL申請中 | X10: 1 | Y10: 46 | Z10: EA | AA10: 650 | AB10: 3 M | AC10: 125 | AD10: 8000 | AE10: 1.5 | AF10: Y | AH10: 4 | AI10: 0823 | AJ10: JSSC | AK10: ARS | AL10: 0 | AN10: LOUDSPEAKER-AMPLIFIER | AO10: 52110 | AP10: A11600 | AQ10: 聲力電話系統技術手冊 | AR10: 堃翊工程有限公司 | AS10: CLQL | AT10: COLLOQUIAL NAME | AU10: 口語名稱 | AV10: Audio Frecuency Amplifie | AW10: 聲力電話放大器 | AX10: STYL | AY10: STYLE DESIGNATOR | AZ10: 外觀型式 | BA10: Style Designator | BB10: 長方形／方形外殼 | BC10: ABMK | BD10: OVERALL WIDTH | BE10: 總寬度 | BF10: 230mm | BG10: 230mm | BH10: ABKW | BI10: OVERALL HEIGHT | BJ10: 總高度 | BK10: 176mm | BL10: 176mm | BR10: C:\\SynologyDrive\\01 JSSC專案\\12 料號申編\\06 次要裝備\\50 聲力電話\\圖片\\09.放大器.jpg | BS10: C | BT10: 4 | BW10: C35 | BX10: B21317 | BY10: 1 | BZ10: 0 | CA10: C | CB10: U | CC10: M | CD10: E | CE10: C | CF10: A | CG10: 00 | CH10: E | CI10: 0 | CJ10: A | CK10: 1973B | CL10: =IF(CK10="","",CJ10&CK10) -> A1973B | CM10: SCM SISTEMAS,S.L. | CN10: 2 | CO10: 3 | CP10: 27NYE0823 | CQ10: FFG | CR10: TA-4CI | CS10: 聲力電話系統 | CT10: 前/後機艙 | CU10: 聲力電話系統 | CV10: Acoustic Telephone System | CW10: 27NYE0823 | CZ10: =IF(DB10="","",DB10&"-"&DC10&"-"&DD10&DE10&"-"&DF10&DG10&"-"&DH10&"-"&DI10&DJ10&"-"&DK10) | DA10: =IF(CY10="","",BX10)
A11: =IF(B11="","",B11&"-"&COUNTIF($B$2:B11,B11)) -> 無-3 | B11: 無 | C11: =IF(F11="","",F11&"-"&COUNTIF(F$2:$H11,F11)) | D11: =IF(G11="","",G11&"-"&COUNTIF(G$2:$H11,G11)) -> 18-9 | E11: =IF(H11="","",H11&"-"&COUNTIF($H$2:H11,H11)) -> 全-10 | G11: 18 | H11: 全 | I11: =IF(Q11="","",COUNTA($Q$2:Q11)) -> 10 | J11: 0009 | K11: 待送出 | L11: A0075 | M11: 聲力電話系統 | N11: 432129 | O11: 149.907 | P11: Exponential Speaker | Q11: 揚聲防水喇叭 | R11: 揚聲防水喇叭 | S11: 5965 | T11: YETL | U11: 申請中 | V11: =T11&U11 -> YETL申請中 | W11: =IF(S11="","",S11&V11) -> 5965YETL申請中 | X11: 1 | Y11: 46 | Z11: EA | AA11: 150 | AB11: 3 M | AC11: 100 | AD11: 10000 | AE11: 1 | AF11: Y | AH11: 4 | AI11: 0823 | AJ11: JSSC | AK11: ARS | AL11: 0 | AN11: Loudspeaker, Electromagnetic | AO11: 00714 | AP11: A11600 | AQ11: 聲力電話系統技術手冊 | AR11: 堃翊工程有限公司 | AS11: CLQL | AT11: COLLOQUIAL NAME | AU11: 口語名稱 | AV11: Exponential Speaker | AW11: 揚聲防水喇叭 | AX11: AKVS | AY11: TRANSDUCER TYPE | AZ11: 換能器類型 | BA11: CONE | BB11: 錐形振膜式換能器 | BC11: ALBY | BD11: USAGE DESIGN | BE11: 設計用途 | BF11: OUTDOOR | BG11: 戶外使用（船艦外部、暴露區） | BH11: AMQY | BI11: INSTALLATION DESIGN | BJ11: 安裝設計 | BK11: NONPORTABLE | BL11: 固定式設備，不可攜 | BM11: ABMK | BN11: OVERALL WIDTH | BO11: 總寬度 | BP11: 222 mm | BQ11: 222 mm，喇叭正面最寬部分 | BR11: C:\\SynologyDrive\\01 JSSC專案\\12 料號申編\\06 次要裝備\\50 聲力電話\\圖片\\10.喇叭.jpg | BS11: C | BT11: 4 | BW11: C35 | BX11: B21317 | BY11: 1 | BZ11: 0 | CA11: C | CB11: U | CC11: M | CD11: E | CE11: C | CF11: A | CG11: 00 | CH11: E | CI11: 0 | CJ11: A | CK11: 1973B | CL11: =IF(CK11="","",CJ11&CK11) -> A1973B | CM11: SCM SISTEMAS,S.L. | CN11: 2 | CO11: 3 | CP11: 27NYE0823 | CQ11: FFG | CR11: TA-4CI | CS11: 聲力電話系統 | CT11: 前/後機艙 | CU11: 聲力電話系統 | CV11: Acoustic Telephone System | CW11: 27NYE0823 | CZ11: =IF(DB11="","",DB11&"-"&DC11&"-"&DD11&DE11&"-"&DF11&DG11&"-"&DH11&"-"&DI11&DJ11&"-"&DK11) | DA11: =IF(CY11="","",BX11)
A12: =IF(B12="","",B12&"-"&COUNTIF($B$2:B12,B12)) | C12: =IF(F12="","",F12&"-"&COUNTIF(F$2:$H12,F12)) | D12: =IF(G12="","",G12&"-"&COUNTIF(G$2:$H12,G12)) -> 18-10 | E12: =IF(H12="","",H12&"-"&COUNTIF($H$2:H12,H12)) -> 全-11 | G12: 18 | H12: 全 | I12: =IF(Q12="","",COUNTA($Q$2:Q12)) -> 11 | J12: 0010 | K12: 繳交成功 | L12: A0016 | M12: 聲力電話系統 | N12: 43212A | O12: 455.010 SCM | P12: Visual Signal Device LD-MG | Q12: 白光警示燈 | R12: 白光警示燈 | S12: 6350 | T12: YETL | U12: 22084 | V12: =T12&U12 -> YETL22084 | W12: =IF(S12="","",S12&V12) -> 6350YETL22084 | X12: 1 | Y12: 45 | Z12: EA | AA12: 40 | AB12: 3 M | AC12: 111.1 | AD12: 9000 | AE12: 1 | AF12: N | AH12: 4 | AI12: 0823 | AJ12: JSSC | AK12: ARS | AL12: 0 | AN12: ALARM,AUDIBLE-VISUAL | AO12: 49541 | AP12: T104-A | AQ12: 聲力電話系統技術手冊 | AR12: 堃翊工程有限公司 | AS12: CLQL | AT12: COLLOQUIAL NAME | AU12: 口語名稱 | AV12: Visual Signal Device LD-MG | AW12: 白光警示燈 | AX12: MATT | AY12: MATERIAL | AZ12: 材質 | BA12: White or red translucent glass | BB12: 白色或紅色半透明玻璃 | BC12: ADAV | BD12: OVERALL DIAMETER | BE12: 總直徑 | BF12: Ø180 mm（outer diameter） | BG12: Ø180 mm（外徑） | BR12: C:\\SynologyDrive\\01 JSSC專案\\12 料號申編\\06 次要裝備\\50 聲力電話\\圖片\\11.警示燈.jpg | BS12: C | BT12: 4 | BW12: C35 | BX12: B21317 | BY12: 1 | BZ12: 0 | CA12: C | CB12: U | CC12: M | CD12: E | CE12: C | CF12: A | CG12: 00 | CH12: E | CI12: 0 | CJ12: A | CK12: 1973B | CL12: =IF(CK12="","",CJ12&CK12) -> A1973B | CM12: SCM SISTEMAS,S.L. | CN12: 2 | CO12: 3 | CP12: 27NYE0823 | CQ12: FFG | CR12: TA-4CI | CS12: 聲力電話系統 | CT12: 前/後機艙 | CU12: 聲力電話系統 | CV12: Acoustic Telephone System | CW12: 27NYE0823 | CZ12: =IF(DB12="","",DB12&"-"&DC12&"-"&DD12&DE12&"-"&DF12&DG12&"-"&DH12&"-"&DI12&DJ12&"-"&DK12) | DA12: =IF(CY12="","",BX12)
A13: =IF(B13="","",B13&"-"&COUNTIF($B$2:B13,B13)) | C13: =IF(F13="","",F13&"-"&COUNTIF(F$2:$H13,F13)) | D13: =IF(G13="","",G13&"-"&COUNTIF(G$2:$H13,G13)) -> 18-11 | E13: =IF(H13="","",H13&"-"&COUNTIF($H$2:H13,H13)) -> 全-12 | G13: 18 | H13: 全 | I13: =IF(Q13="","",COUNTA($Q$2:Q13)) -> 12 | J13: 0011 | K13: 繳交成功 | L13: A0017 | M13: 聲力電話系統 | N13: 43212B | O13: 358.004 SCM | P13: Stowage box(For one telephone) CJ - EST -1-X | Q13: 頭戴式聲力電話放置箱 CJ - EST -1-X(單格) | R13: 聲力電話放置箱-單 | S13: 5965 | T13: YETL | U13: 22083 | V13: =T13&U13 -> YETL22083 | W13: =IF(S13="","",S13&V13) -> 5965YETL22083 | X13: 1 | Y13: 59 | Z13: EA | AA13: 120 | AB13: 3 M | AC13: 50 | AD13: 20000 | AE13: 0.25 | AF13: N | AH13: 4 | AI13: 0823 | AJ13: JSSC | AK13: ARS | AL13: 0 | AN13: BOX,HANDSET STORAGE | AO13: 41713 | AP13: A06600 | AQ13: 聲力電話系統技術手冊 | AR13: 堃翊工程有限公司 | AS13: CLQL | AT13: COLLOQUIAL NAME | AU13: 口語名稱 | AV13: Stowage box(For one telephone) CJ - EST -1-X | AW13: 頭戴式聲力電話放置箱 CJ - EST -1-X(單格) | AX13: STYL | AY13: STYLE DESIGNATOR | AZ13: 外觀型式 | BA13: Headset storage with mounting holes | BB13: 附安裝孔的耳機收納盒 | BC13: ABMK | BD13: OVERALL WIDTH | BE13: 總寬度 | BF13: 265 mm | BG13: 265毫米(左右) | BH13: ABKW | BI13: OVERALL HEIGHT | BJ13: 總高度 | BK13: 273mm | BL13: 273毫米(上下) | BM13: MATT | BN13: MATERIAL | BO13: 材質 | BP13: SUS316 stainless steel | BQ13: SUS316 不鏽鋼 | BR13: C:\\SynologyDrive\\01 JSSC專案\\12 料號申編\\06 次要裝備\\50 聲力電話\\圖片\\12.聲力電話放置箱-單.png | BS13: C | BT13: 4 | BW13: C35 | BX13: B21317 | BY13: 1 | BZ13: 0 | CA13: C | CB13: U | CC13: M | CD13: E | CE13: C | CF13: A | CG13: 00 | CH13: E | CI13: 0 | CJ13: A | CK13: 1973B | CL13: =IF(CK13="","",CJ13&CK13) -> A1973B | CM13: SCM SISTEMAS,S.L. | CN13: 2 | CO13: 3 | CP13: 27NYE0823 | CQ13: FFG | CR13: TA-4CI | CS13: 聲力電話系統 | CT13: 前/後機艙 | CU13: 聲力電話系統 | CV13: Acoustic Telephone System | CW13: 27NYE0823 | CZ13: =IF(DB13="","",DB13&"-"&DC13&"-"&DD13&DE13&"-"&DF13&DG13&"-"&DH13&"-"&DI13&DJ13&"-"&DK13) | DA13: =IF(CY13="","",BX13)
A14: =IF(B14="","",B14&"-"&COUNTIF($B$2:B14,B14)) | C14: =IF(F14="","",F14&"-"&COUNTIF(F$2:$H14,F14)) | D14: =IF(G14="","",G14&"-"&COUNTIF(G$2:$H14,G14)) -> 18-12 | E14: =IF(H14="","",H14&"-"&COUNTIF($H$2:H14,H14)) -> 全-13 | G14: 18 | H14: 全 | I14: =IF(Q14="","",COUNTA($Q$2:Q14)) -> 13 | J14: 0012 | K14: 繳交成功 | L14: A0018 | M14: 聲力電話系統 | N14: 43212C | O14: 358.005 SCM | P14: Stowage box(For two telephones) CJ - EST -2-X | Q14: 頭戴式聲力電話放置箱CJ - EST -2-X(雙格) | R14: 聲力電話放置箱-雙 | S14: 5965 | T14: YETL | U14: 22082 | V14: =T14&U14 -> YETL22082 | W14: =IF(S14="","",S14&V14) -> 5965YETL22082 | X14: 1 | Y14: 16 | Z14: EA | AA14: 150 | AB14: 3 M | AC14: 50 | AD14: 20000 | AE14: 0.25 | AF14: N | AH14: 4 | AI14: 0823 | AJ14: JSSC | AK14: ARS | AL14: 0 | AN14: BOX,HANDSET STORAGE | AO14: 41713 | AP14: A06600 | AQ14: 聲力電話系統技術手冊 | AR14: 堃翊工程有限公司 | AS14: CLQL | AT14: COLLOQUIAL NAME | AU14: 口語名稱 | AV14: Stowage box(For two telephones) CJ - EST -2-X | AW14: 頭戴式聲力電話放置箱CJ - EST -2-X(雙格) | AX14: STYL | AY14: STYLE DESIGNATOR | AZ14: 外觀型式 | BA14: Headset storage with mounting holes | BB14: 附安裝孔的耳機收納盒 | BC14: ABMK | BD14: OVERALL WIDTH | BE14: 總寬度 | BF14: 326 mm | BG14: 326毫米(左右) | BH14: ABKW | BI14: OVERALL HEIGHT | BJ14: 總高度 | BK14: 273mm | BL14: 273毫米(上下) | BM14: MATT | BN14: MATERIAL | BO14: 材質 | BP14: SUS316 stainless steel | BQ14: SUS316 不鏽鋼 | BR14: C:\\SynologyDrive\\01 JSSC專案\\12 料號申編\\06 次要裝備\\50 聲力電話\\圖片\\13.聲力電話放置箱-雙.jpg | BS14: C | BT14: 4 | BW14: C35 | BX14: B21317 | BY14: 1 | BZ14: 0 | CA14: C | CB14: U | CC14: M | CD14: E | CE14: C | CF14: A | CG14: 00 | CH14: E | CI14: 0 | CJ14: A | CK14: 1973B | CL14: =IF(CK14="","",CJ14&CK14) -> A1973B | CM14: SCM SISTEMAS,S.L. | CN14: 2 | CO14: 3 | CP14: 27NYE0823 | CQ14: FFG | CR14: TA-4CI | CS14: 聲力電話系統 | CT14: 前/後機艙 | CU14: 聲力電話系統 | CV14: Acoustic Telephone System | CW14: 27NYE0823 | CZ14: =IF(DB14="","",DB14&"-"&DC14&"-"&DD14&DE14&"-"&DF14&DG14&"-"&DH14&"-"&DI14&DJ14&"-"&DK14) | DA14: =IF(CY14="","",BX14)
A15: =IF(B15="","",B15&"-"&COUNTIF($B$2:B15,B15)) | C15: =IF(F15="","",F15&"-"&COUNTIF(F$2:$H15,F15)) | D15: =IF(G15="","",G15&"-"&COUNTIF(G$2:$H15,G15)) -> 18-13 | E15: =IF(H15="","",H15&"-"&COUNTIF($H$2:H15,H15)) -> 全-14 | G15: 18 | H15: 全 | I15: =IF(Q15="","",COUNTA($Q$2:Q15)) -> 14 | J15: 0013 | K15: 繳交成功 | L15: A0019 | M15: 聲力電話系統 | N15: 43212D | O15: 455.003 | P15: Relay box to activate additional devices. RCB-110 | Q15: 聲力電話繼電器控制盒 | R15: 繼電器控制盒 | S15: 5945 | T15: YETL | U15: 22091 | V15: =T15&U15 -> YETL22091 | W15: =IF(S15="","",S15&V15) -> 5945YETL22091 | X15: 1 | Y15: 46 | Z15: EA | AA15: 50 | AB15: 3 M | AC15: 90 | AD15: 11000 | AE15: 1.5 | AF15: N | AH15: 4 | AI15: 0823 | AJ15: JSSC | AK15: ARS | AL15: 0 | AN15: RELAY ASSEMBLY | AO15: 00447 | AP15: T142-B | AQ15: 聲力電話系統技術手冊 | AR15: 堃翊工程有限公司 | AS15: CLQL | AT15: COLLOQUIAL NAME | AU15: 口語名稱 | AV15: Relay box to activate additional devices. RCB-110 | AW15: 聲力電話繼電器控制盒 | AX15: APCK | AY15: INDIVIDUAL RELAY QUANTITY | AZ15: 單一繼電器數量 | BA15: 1 | BB15: 1 | BC15: ABKW | BD15: OVERALL HEIGHT | BE15: 總高 | BF15: 175 mm | BG15: 175 毫米(上下) | BH15: ABMK | BI15: OVERALL WIDTH | BJ15: 總寬 | BK15: 125 mm | BL15: 125 毫米(左右) | BM15: ABNM | BN15: THICKNESS | BO15: 厚度 | BP15: 100 mm | BQ15: 總深度100 毫米(前後) | BR15: C:\\SynologyDrive\\01 JSSC專案\\12 料號申編\\06 次要裝備\\50 聲力電話\\圖片\\14_聲力電話繼電器控制盒.jpg | BS15: C | BT15: 4 | BW15: C35 | BX15: B21317 | BY15: 1 | BZ15: 0 | CA15: C | CB15: U | CC15: M | CD15: E | CE15: C | CF15: A | CG15: 00 | CH15: E | CI15: 0 | CJ15: A | CK15: 1973B | CL15: =IF(CK15="","",CJ15&CK15) -> A1973B | CM15: SCM SISTEMAS,S.L. | CN15: 2 | CO15: 3 | CP15: 27NYE0823 | CQ15: FFG | CR15: TA-4CI | CS15: 聲力電話系統 | CT15: 前/後機艙 | CU15: 聲力電話系統 | CV15: Acoustic Telephone System | CW15: 27NYE0823 | CZ15: =IF(DB15="","",DB15&"-"&DC15&"-"&DD15&DE15&"-"&DF15&DG15&"-"&DH15&"-"&DI15&DJ15&"-"&DK15) | DA15: =IF(CY15="","",BX15)
A16: =IF(B16="","",B16&"-"&COUNTIF($B$2:B16,B16)) | C16: =IF(F16="","",F16&"-"&COUNTIF(F$2:$H16,F16)) | D16: =IF(G16="","",G16&"-"&COUNTIF(G$2:$H16,G16)) | E16: =IF(H16="","",H16&"-"&COUNTIF($H$2:H16,H16)) | I16: =IF(Q16="","",COUNTA($Q$2:Q16)) | V16: =T16&U16 | W16: =IF(S16="","",S16&V16) | CL16: =IF(CK16="","",CJ16&CK16) | CZ16: =IF(DB16="","",DB16&"-"&DC16&"-"&DD16&DE16&"-"&DF16&DG16&"-"&DH16&"-"&DI16&DJ16&"-"&DK16) | DA16: =IF(CY16="","",BX16)
A17: =IF(B17="","",B17&"-"&COUNTIF($B$2:B17,B17)) | C17: =IF(F17="","",F17&"-"&COUNTIF(F$2:$H17,F17)) | D17: =IF(G17="","",G17&"-"&COUNTIF(G$2:$H17,G17)) | E17: =IF(H17="","",H17&"-"&COUNTIF($H$2:H17,H17)) | I17: =IF(Q17="","",COUNTA($Q$2:Q17)) | V17: =T17&U17 | W17: =IF(S17="","",S17&V17) | CL17: =IF(CK17="","",CJ17&CK17) | CZ17: =IF(DB17="","",DB17&"-"&DC17&"-"&DD17&DE17&"-"&DF17&DG17&"-"&DH17&"-"&DI17&DJ17&"-"&DK17) | DA17: =IF(CY17="","",BX17)
A18: =IF(B18="","",B18&"-"&COUNTIF($B$2:B18,B18)) | C18: =IF(F18="","",F18&"-"&COUNTIF(F$2:$H18,F18)) | D18: =IF(G18="","",G18&"-"&COUNTIF(G$2:$H18,G18)) | E18: =IF(H18="","",H18&"-"&COUNTIF($H$2:H18,H18)) | I18: =IF(Q18="","",COUNTA($Q$2:Q18)) | V18: =T18&U18 | W18: =IF(S18="","",S18&V18) | CL18: =IF(CK18="","",CJ18&CK18) | CZ18: =IF(DB18="","",DB18&"-"&DC18&"-"&DD18&DE18&"-"&DF18&DG18&"-"&DH18&"-"&DI18&DJ18&"-"&DK18) | DA18: =IF(CY18="","",BX18)
A19: =IF(B19="","",B19&"-"&COUNTIF($B$2:B19,B19)) | C19: =IF(F19="","",F19&"-"&COUNTIF(F$2:$H19,F19)) | D19: =IF(G19="","",G19&"-"&COUNTIF(G$2:$H19,G19)) | E19: =IF(H19="","",H19&"-"&COUNTIF($H$2:H19,H19)) | I19: =IF(Q19="","",COUNTA($Q$2:Q19)) | V19: =T19&U19 | W19: =IF(S19="","",S19&V19) | CL19: =IF(CK19="","",CJ19&CK19) | CZ19: =IF(DB19="","",DB19&"-"&DC19&"-"&DD19&DE19&"-"&DF19&DG19&"-"&DH19&"-"&DI19&DJ19&"-"&DK19) | DA19: =IF(CY19="","",BX19)
A20: =IF(B20="","",B20&"-"&COUNTIF($B$2:B20,B20)) | C20: =IF(F20="","",F20&"-"&COUNTIF(F$2:$H20,F20)) | D20: =IF(G20="","",G20&"-"&COUNTIF(G$2:$H20,G20)) | E20: =IF(H20="","",H20&"-"&COUNTIF($H$2:H20,H20)) | I20: =IF(Q20="","",COUNTA($Q$2:Q20)) | V20: =T20&U20 | W20: =IF(S20="","",S20&V20) | CL20: =IF(CK20="","",CJ20&CK20) | CZ20: =IF(DB20="","",DB20&"-"&DC20&"-"&DD20&DE20&"-"&DF20&DG20&"-"&DH20&"-"&DI20&DJ20&"-"&DK20) | DA20: =IF(CY20="","",BX20)
A21: =IF(B21="","",B21&"-"&COUNTIF($B$2:B21,B21)) | C21: =IF(F21="","",F21&"-"&COUNTIF(F$2:$H21,F21)) | D21: =IF(G21="","",G21&"-"&COUNTIF(G$2:$H21,G21)) | E21: =IF(H21="","",H21&"-"&COUNTIF($H$2:H21,H21)) | I21: =IF(Q21="","",COUNTA($Q$2:Q21)) | V21: =T21&U21 | W21: =IF(S21="","",S21&V21) | CL21: =IF(CK21="","",CJ21&CK21) | CZ21: =IF(DB21="","",DB21&"-"&DC21&"-"&DD21&DE21&"-"&DF21&DG21&"-"&DH21&"-"&DI21&DJ21&"-"&DK21) | DA21: =IF(CY21="","",BX21)
A22: =IF(B22="","",B22&"-"&COUNTIF($B$2:B22,B22)) | C22: =IF(F22="","",F22&"-"&COUNTIF(F$2:$H22,F22)) | D22: =IF(G22="","",G22&"-"&COUNTIF(G$2:$H22,G22)) | E22: =IF(H22="","",H22&"-"&COUNTIF($H$2:H22,H22)) | I22: =IF(Q22="","",COUNTA($Q$2:Q22)) | V22: =T22&U22 | W22: =IF(S22="","",S22&V22) | CL22: =IF(CK22="","",CJ22&CK22) | CZ22: =IF(DB22="","",DB22&"-"&DC22&"-"&DD22&DE22&"-"&DF22&DG22&"-"&DH22&"-"&DI22&DJ22&"-"&DK22) | DA22: =IF(CY22="","",BX22)
A23: =IF(B23="","",B23&"-"&COUNTIF($B$2:B23,B23)) | C23: =IF(F23="","",F23&"-"&COUNTIF(F$2:$H23,F23)) | D23: =IF(G23="","",G23&"-"&COUNTIF(G$2:$H23,G23)) | E23: =IF(H23="","",H23&"-"&COUNTIF($H$2:H23,H23)) | I23: =IF(Q23="","",COUNTA($Q$2:Q23)) | V23: =T23&U23 | W23: =IF(S23="","",S23&V23) | CL23: =IF(CK23="","",CJ23&CK23) | CZ23: =IF(DB23="","",DB23&"-"&DC23&"-"&DD23&DE23&"-"&DF23&DG23&"-"&DH23&"-"&DI23&DJ23&"-"&DK23) | DA23: =IF(CY23="","",BX23)
A24: =IF(B24="","",B24&"-"&COUNTIF($B$2:B24,B24)) | C24: =IF(F24="","",F24&"-"&COUNTIF(F$2:$H24,F24)) | D24: =IF(G24="","",G24&"-"&COUNTIF(G$2:$H24,G24)) | E24: =IF(H24="","",H24&"-"&COUNTIF($H$2:H24,H24)) | I24: =IF(Q24="","",COUNTA($Q$2:Q24)) | V24: =T24&U24 | W24: =IF(S24="","",S24&V24) | CL24: =IF(CK24="","",CJ24&CK24) | CZ24: =IF(DB24="","",DB24&"-"&DC24&"-"&DD24&DE24&"-"&DF24&DG24&"-"&DH24&"-"&DI24&DJ24&"-"&DK24) | DA24: =IF(CY24="","",BX24)
A25: =IF(B25="","",B25&"-"&COUNTIF($B$2:B25,B25)) | C25: =IF(F25="","",F25&"-"&COUNTIF(F$2:$H25,F25)) | D25: =IF(G25="","",G25&"-"&COUNTIF(G$2:$H25,G25)) | E25: =IF(H25="","",H25&"-"&COUNTIF($H$2:H25,H25)) | I25: =IF(Q25="","",COUNTA($Q$2:Q25)) | V25: =T25&U25 | W25: =IF(S25="","",S25&V25) | CL25: =IF(CK25="","",CJ25&CK25) | CZ25: =IF(DB25="","",DB25&"-"&DC25&"-"&DD25&DE25&"-"&DF25&DG25&"-"&DH25&"-"&DI25&DJ25&"-"&DK25) | DA25: =IF(CY25="","",BX25)
A26: =IF(B26="","",B26&"-"&COUNTIF($B$2:B26,B26)) | C26: =IF(F26="","",F26&"-"&COUNTIF(F$2:$H26,F26)) | D26: =IF(G26="","",G26&"-"&COUNTIF(G$2:$H26,G26)) | E26: =IF(H26="","",H26&"-"&COUNTIF($H$2:H26,H26)) | I26: =IF(Q26="","",COUNTA($Q$2:Q26)) | V26: =T26&U26 | W26: =IF(S26="","",S26&V26) | CL26: =IF(CK26="","",CJ26&CK26) | CZ26: =IF(DB26="","",DB26&"-"&DC26&"-"&DD26&DE26&"-"&DF26&DG26&"-"&DH26&"-"&DI26&DJ26&"-"&DK26) | DA26: =IF(CY26="","",BX26)
A27: =IF(B27="","",B27&"-"&COUNTIF($B$2:B27,B27)) | C27: =IF(F27="","",F27&"-"&COUNTIF(F$2:$H27,F27)) | D27: =IF(G27="","",G27&"-"&COUNTIF(G$2:$H27,G27)) | E27: =IF(H27="","",H27&"-"&COUNTIF($H$2:H27,H27)) | I27: =IF(Q27="","",COUNTA($Q$2:Q27)) | V27: =T27&U27 | W27: =IF(S27="","",S27&V27) | CL27: =IF(CK27="","",CJ27&CK27) | CZ27: =IF(DB27="","",DB27&"-"&DC27&"-"&DD27&DE27&"-"&DF27&DG27&"-"&DH27&"-"&DI27&DJ27&"-"&DK27) | DA27: =IF(CY27="","",BX27)
... A100: =IF(B100="","",B100&"-"&COUNTIF($B$2:B100,B100)) | C100: =IF(F100="","",F100&"-"&COUNTIF(F$2:$H100,F100)) | D100: =IF(G100="","",G100&"-"&COUNTIF(G$2:$H100,G100)) | E100: =IF(H100="","",H100&"-"&COUNTIF($H$2:H100,H100)) | I100: =IF(Q100="","",COUNTA($Q$2:Q100)) | V100: =T100&U100 | W100: =IF(S100="","",S100&V100) | CL100: =IF(CK100="","",CJ100&CK100) | CZ100: =IF(DB100="","",DB100&"-"&DC100&"-"&DD100&DE100&"-"&DF100&DG100&"-"&DH100&"-"&DI100&DJ100&"-"&DK100) | DA100: =IF(CY100="","",BX100)

Sheet 有料號
A1: 有 | B1: 項次 | C1: 統一組類別 | D1: 品項識別碼 | E1: 武器系統代號 | F1: 英文品名 | G1: 中文品名 | H1: 會計編號 | I1: 撥發單位 | J1: 美金單價 | K1: 單位包裝量 | L1: 存儲壽限代號 | M1: 檔別代號 | N1: 品名代號 | O1: 機密性代號 | P1: 消耗性代號 | Q1: 規格指示 | R1: 海軍軍品來源 | S1: 儲存型式 | T1: 壽限處理代號 | U1: 製造能量 | V1: 修理能量 | W1: 配件號碼(P/N) | X1: 廠商來源代號 | Y1: 廠家登記代號 | Z1: 參考號獲得程度 | AA1: 參考號獲得來源 | AB1: 單機識別碼(CID)
B2: =IF(C2="","",COUNTA($C$2:C2)) | C2: =IFERROR(VLOOKUP($A$1&"-"&ROW(C1),基本資料填寫!$A:$DN,COLUMN(基本資料填寫!S2),0),"") | D2: =IFERROR(VLOOKUP($A$1&"-"&ROW(D1),基本資料填寫!$A:$DN,COLUMN(基本資料填寫!V2),0),"") | E2: =IFERROR(VLOOKUP($A$1&"-"&ROW(E1),基本資料填寫!$A:$DN,COLUMN(基本資料填寫!BW2),0),"") | F2: =IFERROR(VLOOKUP($A$1&"-"&ROW(F1),基本資料填寫!$A:$DN,COLUMN(基本資料填寫!AN2),0),"") | G2: =IFERROR(VLOOKUP($A$1&"-"&ROW(H1),基本資料填寫!$A:$DN,COLUMN(基本資料填寫!R2),0),"") | H2: =IFERROR(VLOOKUP($A$1&"-"&ROW(X1),基本資料填寫!$A:$DN,COLUMN(基本資料填寫!BX2),0),"") | I2: =IFERROR(VLOOKUP($A$1&"-"&ROW(P1),基本資料填寫!$A:$DN,COLUMN(基本資料填寫!Z2),0),"") | J2: =IFERROR(VLOOKUP($A$1&"-"&ROW(Q1),基本資料填寫!$A:$DN,COLUMN(基本資料填寫!AA2),0),"") | K2: =IFERROR(VLOOKUP($A$1&"-"&ROW(Y1),基本資料填寫!$A:$DN,COLUMN(基本資料填寫!BY2),0),"") | L2: =IFERROR(VLOOKUP($A$1&"-"&ROW(Z1),基本資料填寫!$A:$DN,COLUMN(基本資料填寫!BZ2),0),"") | M2: =IFERROR(VLOOKUP($A$1&"-"&ROW(AA1),基本資料填寫!$A:$DN,COLUMN(基本資料填寫!CA2),0),"") | N2: =IFERROR(VLOOKUP($A$1&"-"&ROW(G1),基本資料填寫!$A:$DN,COLUMN(基本資料填寫!AO2),0),"") | O2: =IFERROR(VLOOKUP($A$1&"-"&ROW(AB1),基本資料填寫!$A:$DN,COLUMN(基本資料填寫!CB2),0),"") | P2: =IFERROR(VLOOKUP($A$1&"-"&ROW(AC1),基本資料填寫!$A:$DN,COLUMN(基本資料填寫!CC2),0),"") | Q2: =IFERROR(VLOOKUP($A$1&"-"&ROW(AD1),基本資料填寫!$A:$DN,COLUMN(基本資料填寫!CD2),0),"") | R2: =IFERROR(VLOOKUP($A$1&"-"&ROW(AE1),基本資料填寫!$A:$DN,COLUMN(基本資料填寫!CE2),0),"") | S2: =IFERROR(VLOOKUP($A$1&"-"&ROW(AF1),基本資料填寫!$A:$DN,COLUMN(基本資料填寫!CF2),0),"") | T2: =IFERROR(VLOOKUP($A$1&"-"&ROW(AG1),基本資料填寫!$A:$DN,COLUMN(基本資料填寫!CG2),0),"") | U2: =IFERROR(VLOOKUP($A$1&"-"&ROW(AH1),基本資料填寫!$A:$DN,COLUMN(基本資料填寫!CH2),0),"") | V2: =IFERROR(VLOOKUP($A$1&"-"&ROW(AI1),基本資料填寫!$A:$DN,COLUMN(基本資料填寫!CI2),0),"") | W2: =IFERROR(VLOOKUP($A$1&"-"&ROW(E1),基本資料填寫!$A:$DN,COLUMN(基本資料填寫!O2),0),"") | X2: =IFERROR(VLOOKUP($A$1&"-"&ROW(AJ1),基本資料填寫!$A:$DN,COLUMN(基本資料填寫!CJ2),0),"") | Y2: =IFERROR(VLOOKUP($A$1&"-"&ROW(AK1),基本資料填寫!$A:$DN,COLUMN(基本資料填寫!CK2),0),"") | Z2: =IFERROR(VLOOKUP($A$1&"-"&ROW(AM1),基本資料填寫!$A:$DN,COLUMN(基本資料填寫!CN2),0),"") | AA2: =IFERROR(VLOOKUP($A$1&"-"&ROW(AN1),基本資料填寫!$A:$DN,COLUMN(基本資料填寫!CO2),0),"") | AB2: =IFERROR(VLOOKUP($A$1&"-"&ROW(AO1),基本資料填寫!$A:$DN,COLUMN(基本資料填寫!CP2),0),"")
B3: =IF(C3="","",COUNTA($C$2:C3)) | C3: =IFERROR(VLOOKUP($A$1&"-"&ROW(C2),基本資料填寫!$A:$DN,COLUMN(基本資料填寫!S3),0),"") | D3: =IFERROR(VLOOKUP($A$1&"-"&ROW(D2),基本資料填寫!$A:$DN,COLUMN(基本資料填寫!V3),0),"") | E3: =IFERROR(VLOOKUP($A$1&"-"&ROW(E2),基本資料填寫!$A:$DN,COLUMN(基本資料填寫!BW3),0),"") | F3: =IFERROR(VLOOKUP($A$1&"-"&ROW(F2),基本資料填寫!$A:$DN,COLUMN(基本資料填寫!AN3),0),"") | G3: =IFERROR(VLOOKUP($A$1&"-"&ROW(H2),基本資料填寫!$A:$DN,COLUMN(基本資料填寫!R3),0),"") | H3: =IFERROR(VLOOKUP($A$1&"-"&ROW(X2),基本資料填寫!$A:$DN,COLUMN(基本資料填寫!BX3),0),"") | I3: =IFERROR(VLOOKUP($A$1&"-"&ROW(P2),基本資料填寫!$A:$DN,COLUMN(基本資料填寫!Z3),0),"") | J3: =IFERROR(VLOOKUP($A$1&"-"&ROW(Q2),基本資料填寫!$A:$DN,COLUMN(基本資料填寫!AA3),0),"") | K3: =IFERROR(VLOOKUP($A$1&"-"&ROW(Y2),基本資料填寫!$A:$DN,COLUMN(基本資料填寫!BY3),0),"") | L3: =IFERROR(VLOOKUP($A$1&"-"&ROW(Z2),基本資料填寫!$A:$DN,COLUMN(基本資料填寫!BZ3),0),"") | M3: =IFERROR(VLOOKUP($A$1&"-"&ROW(AA2),基本資料填寫!$A:$DN,COLUMN(基本資料填寫!CA3),0),"") | N3: =IFERROR(VLOOKUP($A$1&"-"&ROW(G2),基本資料填寫!$A:$DN,COLUMN(基本資料填寫!AO3),0),"") | O3: =IFERROR(VLOOKUP($A$1&"-"&ROW(AB2),基本資料填寫!$A:$DN,COLUMN(基本資料填寫!CB3),0),"") | P3: =IFERROR(VLOOKUP($A$1&"-"&ROW(AC2),基本資料填寫!$A:$DN,COLUMN(基本資料填寫!CC3),0),"") | Q3: =IFERROR(VLOOKUP($A$1&"-"&ROW(AD2),基本資料填寫!$A:$DN,COLUMN(基本資料填寫!CD3),0),"") | R3: =IFERROR(VLOOKUP($A$1&"-"&ROW(AE2),基本資料填寫!$A:$DN,COLUMN(基本資料填寫!CE3),0),"") | S3: =IFERROR(VLOOKUP($A$1&"-"&ROW(AF2),基本資料填寫!$A:$DN,COLUMN(基本資料填寫!CF3),0),"") | T3: =IFERROR(VLOOKUP($A$1&"-"&ROW(AG2),基本資料填寫!$A:$DN,COLUMN(基本資料填寫!CG3),0),"") | U3: =IFERROR(VLOOKUP($A$1&"-"&ROW(AH2),基本資料填寫!$A:$DN,COLUMN(基本資料填寫!CH3),0),"") | V3: =IFERROR(VLOOKUP($A$1&"-"&ROW(AI2),基本資料填寫!$A:$DN,COLUMN(基本資料填寫!CI3),0),"") | W3: =IFERROR(VLOOKUP($A$1&"-"&ROW(E2),基本資料填寫!$A:$DN,COLUMN(基本資料填寫!O3),0),"") | X3: =IFERROR(VLOOKUP($A$1&"-"&ROW(AJ2),基本資料填寫!$A:$DN,COLUMN(基本資料填寫!CJ3),0),"") | Y3: =IFERROR(VLOOKUP($A$1&"-"&ROW(AK2),基本資料填寫!$A:$DN,COLUMN(基本資料填寫!CK3),0),"") | Z3: =IFERROR(VLOOKUP($A$1&"-"&ROW(AM2),基本資料填寫!$A:$DN,COLUMN(基本資料填寫!CN3),0),"") | AA3: =IFERROR(VLOOKUP($A$1&"-"&ROW(AN2),基本資料填寫!$A:$DN,COLUMN(基本資料填寫!CO3),0),"") | AB3: =IFERROR(VLOOKUP($A$1&"-"&ROW(AO2),基本資料填寫!$A:$DN,COLUMN(基本資料填寫!CP3),0),"")
B4: =IF(C4="","",COUNTA($C$2:C4)) | C4: =IFERROR(VLOOKUP($A$1&"-"&ROW(C3),基本資料填寫!$A:$DN,COLUMN(基本資料填寫!S4),0),"") | D4: =IFERROR(VLOOKUP($A$1&"-"&ROW(D3),基本資料填寫!$A:$DN,COLUMN(基本資料填寫!V4),0),"") | E4: =IFERROR(VLOOKUP($A$1&"-"&ROW(E3),基本資料填寫!$A:$DN,COLUMN(基本資料填寫!BW4),0),"") | F4: =IFERROR(VLOOKUP($A$1&"-"&ROW(F3),基本資料填寫!$A:$DN,COLUMN(基本資料填寫!AN4),0),"") | G4: =IFERROR(VLOOKUP($A$1&"-"&ROW(H3),基本資料填寫!$A:$DN,COLUMN(基本資料填寫!R4),0),"") | H4: =IFERROR(VLOOKUP($A$1&"-"&ROW(X3),基本資料填寫!$A:$DN,COLUMN(基本資料填寫!BX4),0),"") | I4: =IFERROR(VLOOKUP($A$1&"-"&ROW(P3),基本資料填寫!$A:$DN,COLUMN(基本資料填寫!Z4),0),"") | J4: =IFERROR(VLOOKUP($A$1&"-"&ROW(Q3),基本資料填寫!$A:$DN,COLUMN(基本資料填寫!AA4),0),"") | K4: =IFERROR(VLOOKUP($A$1&"-"&ROW(Y3),基本資料填寫!$A:$DN,COLUMN(基本資料填寫!BY4),0),"") | L4: =IFERROR(VLOOKUP($A$1&"-"&ROW(Z3),基本資料填寫!$A:$DN,COLUMN(基本資料填寫!BZ4),0),"") | M4: =IFERROR(VLOOKUP($A$1&"-"&ROW(AA3),基本資料填寫!$A:$DN,COLUMN(基本資料填寫!CA4),0),"") | N4: =IFERROR(VLOOKUP($A$1&"-"&ROW(G3),基本資料填寫!$A:$DN,COLUMN(基本資料填寫!AO4),0),"") | O4: =IFERROR(VLOOKUP($A$1&"-"&ROW(AB3),基本資料填寫!$A:$DN,COLUMN(基本資料填寫!CB4),0),"") | P4: =IFERROR(VLOOKUP($A$1&"-"&ROW(AC3),基本資料填寫!$A:$DN,COLUMN(基本資料填寫!CC4),0),"") | Q4: =IFERROR(VLOOKUP($A$1&"-"&ROW(AD3),基本資料填寫!$A:$DN,COLUMN(基本資料填寫!CD4),0),"") | R4: =IFERROR(VLOOKUP($A$1&"-"&ROW(AE3),基本資料填寫!$A:$DN,COLUMN(基本資料填寫!CE4),0),"") | S4: =IFERROR(VLOOKUP($A$1&"-"&ROW(AF3),基本資料填寫!$A:$DN,COLUMN(基本資料填寫!CF4),0),"") | T4: =IFERROR(VLOOKUP($A$1&"-"&ROW(AG3),基本資料填寫!$A:$DN,COLUMN(基本資料填寫!CG4),0),"") | U4: =IFERROR(VLOOKUP($A$1&"-"&ROW(AH3),基本資料填寫!$A:$DN,COLUMN(基本資料填寫!CH4),0),"") | V4: =IFERROR(VLOOKUP($A$1&"-"&ROW(AI3),基本資料填寫!$A:$DN,COLUMN(基本資料填寫!CI4),0),"") | W4: =IFERROR(VLOOKUP($A$1&"-"&ROW(E3),基本資料填寫!$A:$DN,COLUMN(基本資料填寫!O4),0),"") | X4: =IFERROR(VLOOKUP($A$1&"-"&ROW(AJ3),基本資料填寫!$A:$DN,COLUMN(基本資料填寫!CJ4),0),"") | Y4: =IFERROR(VLOOKUP($A$1&"-"&ROW(AK3),基本資料填寫!$A:$DN,COLUMN(基本資料填寫!CK4),0),"") | Z4: =IFERROR(VLOOKUP($A$1&"-"&ROW(AM3),基本資料填寫!$A:$DN,COLUMN(基本資料填寫!CN4),0),"") | AA4: =IFERROR(VLOOKUP($A$1&"-"&ROW(AN3),基本資料填寫!$A:$DN,COLUMN(基本資料填寫!CO4),0),"") | AB4: =IFERROR(VLOOKUP($A$1&"-"&ROW(AO3),基本資料填寫!$A:$DN,COLUMN(基本資料填寫!CP4),0),"")
B5: =IF(C5="","",COUNTA($C$2:C5)) | C5: =IFERROR(VLOOKUP($A$1&"-"&ROW(C4),基本資料填寫!$A:$DN,COLUMN(基本資料填寫!S5),0),"") | D5: =IFERROR(VLOOKUP($A$1&"-"&ROW(D4),基本資料填寫!$A:$DN,COLUMN(基本資料填寫!V5),0),"") | E5: =IFERROR(VLOOKUP($A$1&"-"&ROW(E4),基本資料填寫!$A:$DN,COLUMN(基本資料填寫!BW5),0),"") | F5: =IFERROR(VLOOKUP($A$1&"-"&ROW(F4),基本資料填寫!$A:$DN,COLUMN(基本資料填寫!AN5),0),"") | G5: =IFERROR(VLOOKUP($A$1&"-"&ROW(H4),基本資料填寫!$A:$DN,COLUMN(基本資料填寫!R5),0),"") | H5: =IFERROR(VLOOKUP($A$1&"-"&ROW(X4),基本資料填寫!$A:$DN,COLUMN(基本資料填寫!BX5),0),"") | I5: =IFERROR(VLOOKUP($A$1&"-"&ROW(P4),基本資料填寫!$A:$DN,COLUMN(基本資料填寫!Z5),0),"") | J5: =IFERROR(VLOOKUP($A$1&"-"&ROW(Q4),基本資料填寫!$A:$DN,COLUMN(基本資料填寫!AA5),0),"") | K5: =IFERROR(VLOOKUP($A$1&"-"&ROW(Y4),基本資料填寫!$A:$DN,COLUMN(基本資料填寫!BY5),0),"") | L5: =IFERROR(VLOOKUP($A$1&"-"&ROW(Z4),基本資料填寫!$A:$DN,COLUMN(基本資料填寫!BZ5),0),"") | M5: =IFERROR(VLOOKUP($A$1&"-"&ROW(AA4),基本資料填寫!$A:$DN,COLUMN(基本資料填寫!CA5),0),"") | N5: =IFERROR(VLOOKUP($A$1&"-"&ROW(G4),基本資料填寫!$A:$DN,COLUMN(基本資料填寫!AO5),0),"") | O5: =IFERROR(VLOOKUP($A$1&"-"&ROW(AB4),基本資料填寫!$A:$DN,COLUMN(基本資料填寫!CB5),0),"") | P5: =IFERROR(VLOOKUP($A$1&"-"&ROW(AC4),基本資料填寫!$A:$DN,COLUMN(基本資料填寫!CC5),0),"") | Q5: =IFERROR(VLOOKUP($A$1&"-"&ROW(AD4),基本資料填寫!$A:$DN,COLUMN(基本資料填寫!CD5),0),"") | R5: =IFERROR(VLOOKUP($A$1&"-"&ROW(AE4),基本資料填寫!$A:$DN,COLUMN(基本資料填寫!CE5),0),"") | S5: =IFERROR(VLOOKUP($A$1&"-"&ROW(AF4),基本資料填寫!$A:$DN,COLUMN(基本資料填寫!CF5),0),"") | T5: =IFERROR(VLOOKUP($A$1&"-"&ROW(AG4),基本資料填寫!$A:$DN,COLUMN(基本資料填寫!CG5),0),"") | U5: =IFERROR(VLOOKUP($A$1&"-"&ROW(AH4),基本資料填寫!$A:$DN,COLUMN(基本資料填寫!CH5),0),"") | V5: =IFERROR(VLOOKUP($A$1&"-"&ROW(AI4),基本資料填寫!$A:$DN,COLUMN(基本資料填寫!CI5),0),"") | W5: =IFERROR(VLOOKUP($A$1&"-"&ROW(E4),基本資料填寫!$A:$DN,COLUMN(基本資料填寫!O5),0),"") | X5: =IFERROR(VLOOKUP($A$1&"-"&ROW(AJ4),基本資料填寫!$A:$DN,COLUMN(基本資料填寫!CJ5),0),"") | Y5: =IFERROR(VLOOKUP($A$1&"-"&ROW(AK4),基本資料填寫!$A:$DN,COLUMN(基本資料填寫!CK5),0),"") | Z5: =IFERROR(VLOOKUP($A$1&"-"&ROW(AM4),基本資料填寫!$A:$DN,COLUMN(基本資料填寫!CN5),0),"") | AA5: =IFERROR(VLOOKUP($A$1&"-"&ROW(AN4),基本資料填寫!$A:$DN,COLUMN(基本資料填寫!CO5),0),"") | AB5: =IFERROR(VLOOKUP($A$1&"-"&ROW(AO4),基本資料填寫!$A:$DN,COLUMN(基本資料填寫!CP5),0),"")
B6: =IF(C6="","",COUNTA($C$2:C6)) | C6: =IFERROR(VLOOKUP($A$1&"-"&ROW(C5),基本資料填寫!$A:$DN,COLUMN(基本資料填寫!S6),0),"") | D6: =IFERROR(VLOOKUP($A$1&"-"&ROW(D5),基本資料填寫!$A:$DN,COLUMN(基本資料填寫!V6),0),"") | E6: =IFERROR(VLOOKUP($A$1&"-"&ROW(E5),基本資料填寫!$A:$DN,COLUMN(基本資料填寫!BW6),0),"") | F6: =IFERROR(VLOOKUP($A$1&"-"&ROW(F5),基本資料填寫!$A:$DN,COLUMN(基本資料填寫!AN6),0),"") | G6: =IFERROR(VLOOKUP($A$1&"-"&ROW(H5),基本資料填寫!$A:$DN,COLUMN(基本資料填寫!R6),0),"") | H6: =IFERROR(VLOOKUP($A$1&"-"&ROW(X5),基本資料填寫!$A:$DN,COLUMN(基本資料填寫!BX6),0),"") | I6: =IFERROR(VLOOKUP($A$1&"-"&ROW(P5),基本資料填寫!$A:$DN,COLUMN(基本資料填寫!Z6),0),"") | J6: =IFERROR(VLOOKUP($A$1&"-"&ROW(Q5),基本資料填寫!$A:$DN,COLUMN(基本資料填寫!AA6),0),"") | K6: =IFERROR(VLOOKUP($A$1&"-"&ROW(Y5),基本資料填寫!$A:$DN,COLUMN(基本資料填寫!BY6),0),"") | L6: =IFERROR(VLOOKUP($A$1&"-"&ROW(Z5),基本資料填寫!$A:$DN,COLUMN(基本資料填寫!BZ6),0),"") | M6: =IFERROR(VLOOKUP($A$1&"-"&ROW(AA5),基本資料填寫!$A:$DN,COLUMN(基本資料填寫!CA6),0),"") | N6: =IFERROR(VLOOKUP($A$1&"-"&ROW(G5),基本資料填寫!$A:$DN,COLUMN(基本資料填寫!AO6),0),"") | O6: =IFERROR(VLOOKUP($A$1&"-"&ROW(AB5),基本資料填寫!$A:$DN,COLUMN(基本資料填寫!CB6),0),"") | P6: =IFERROR(VLOOKUP($A$1&"-"&ROW(AC5),基本資料填寫!$A:$DN,COLUMN(基本資料填寫!CC6),0),"") | Q6: =IFERROR(VLOOKUP($A$1&"-"&ROW(AD5),基本資料填寫!$A:$DN,COLUMN(基本資料填寫!CD6),0),"") | R6: =IFERROR(VLOOKUP($A$1&"-"&ROW(AE5),基本資料填寫!$A:$DN,COLUMN(基本資料填寫!CE6),0),"") | S6: =IFERROR(VLOOKUP($A$1&"-"&ROW(AF5),基本資料填寫!$A:$DN,COLUMN(基本資料填寫!CF6),0),"") | T6: =IFERROR(VLOOKUP($A$1&"-"&ROW(AG5),基本資料填寫!$A:$DN,COLUMN(基本資料填寫!CG6),0),"") | U6: =IFERROR(VLOOKUP($A$1&"-"&ROW(AH5),基本資料填寫!$A:$DN,COLUMN(基本資料填寫!CH6),0),"") | V6: =IFERROR(VLOOKUP($A$1&"-"&ROW(AI5),基本資料填寫!$A:$DN,COLUMN(基本資料填寫!CI6),0),"") | W6: =IFERROR(VLOOKUP($A$1&"-"&ROW(E5),基本資料填寫!$A:$DN,COLUMN(基本資料填寫!O6),0),"") | X6: =IFERROR(VLOOKUP($A$1&"-"&ROW(AJ5),基本資料填寫!$A:$DN,COLUMN(基本資料填寫!CJ6),0),"") | Y6: =IFERROR(VLOOKUP($A$1&"-"&ROW(AK5),基本資料填寫!$A:$DN,COLUMN(基本資料填寫!CK6),0),"") | Z6: =IFERROR(VLOOKUP($A$1&"-"&ROW(AM5),基本資料填寫!$A:$DN,COLUMN(基本資料填寫!CN6),0),"") | AA6: =IFERROR(VLOOKUP($A$1&"-"&ROW(AN5),基本資料填寫!$A:$DN,COLUMN(基本資料填寫!CO6),0),"") | AB6: =IFERROR(VLOOKUP($A$1&"-"&ROW(AO5),基本資料填寫!$A:$DN,COLUMN(基本資料填寫!CP6),0),"")
B7: =IF(C7="","",COUNTA($C$2:C7)) | C7: =IFERROR(VLOOKUP($A$1&"-"&ROW(C6),基本資料填寫!$A:$DN,COLUMN(基本資料填寫!S7),0),"") | D7: =IFERROR(VLOOKUP($A$1&"-"&ROW(D6),基本資料填寫!$A:$DN,COLUMN(基本資料填寫!V7),0),"") | E7: =IFERROR(VLOOKUP($A$1&"-"&ROW(E6),基本資料填寫!$A:$DN,COLUMN(基本資料填寫!BW7),0),"") | F7: =IFERROR(VLOOKUP($A$1&"-"&ROW(F6),基本資料填寫!$A:$DN,COLUMN(基本資料填寫!AN7),0),"") | G7: =IFERROR(VLOOKUP($A$1&"-"&ROW(H6),基本資料填寫!$A:$DN,COLUMN(基本資料填寫!R7),0),"") | H7: =IFERROR(VLOOKUP($A$1&"-"&ROW(X6),基本資料填寫!$A:$DN,COLUMN(基本資料填寫!BX7),0),"") | I7: =IFERROR(VLOOKUP($A$1&"-"&ROW(P6),基本資料填寫!$A:$DN,COLUMN(基本資料填寫!Z7),0),"") | J7: =IFERROR(VLOOKUP($A$1&"-"&ROW(Q6),基本資料填寫!$A:$DN,COLUMN(基本資料填寫!AA7),0),"") | K7: =IFERROR(VLOOKUP($A$1&"-"&ROW(Y6),基本資料填寫!$A:$DN,COLUMN(基本資料填寫!BY7),0),"") | L7: =IFERROR(VLOOKUP($A$1&"-"&ROW(Z6),基本資料填寫!$A:$DN,COLUMN(基本資料填寫!BZ7),0),"") | M7: =IFERROR(VLOOKUP($A$1&"-"&ROW(AA6),基本資料填寫!$A:$DN,COLUMN(基本資料填寫!CA7),0),"") | N7: =IFERROR(VLOOKUP($A$1&"-"&ROW(G6),基本資料填寫!$A:$DN,COLUMN(基本資料填寫!AO7),0),"") | O7: =IFERROR(VLOOKUP($A$1&"-"&ROW(AB6),基本資料填寫!$A:$DN,COLUMN(基本資料填寫!CB7),0),"") | P7: =IFERROR(VLOOKUP($A$1&"-"&ROW(AC6),基本資料填寫!$A:$DN,COLUMN(基本資料填寫!CC7),0),"") | Q7: =IFERROR(VLOOKUP($A$1&"-"&ROW(AD6),基本資料填寫!$A:$DN,COLUMN(基本資料填寫!CD7),0),"") | R7: =IFERROR(VLOOKUP($A$1&"-"&ROW(AE6),基本資料填寫!$A:$DN,COLUMN(基本資料填寫!CE7),0),"") | S7: =IFERROR(VLOOKUP($A$1&"-"&ROW(AF6),基本資料填寫!$A:$DN,COLUMN(基本資料填寫!CF7),0),"") | T7: =IFERROR(VLOOKUP($A$1&"-"&ROW(AG6),基本資料填寫!$A:$DN,COLUMN(基本資料填寫!CG7),0),"") | U7: =IFERROR(VLOOKUP($A$1&"-"&ROW(AH6),基本資料填寫!$A:$DN,COLUMN(基本資料填寫!CH7),0),"") | V7: =IFERROR(VLOOKUP($A$1&"-"&ROW(AI6),基本資料填寫!$A:$DN,COLUMN(基本資料填寫!CI7),0),"") | W7: =IFERROR(VLOOKUP($A$1&"-"&ROW(E6),基本資料填寫!$A:$DN,COLUMN(基本資料填寫!O7),0),"") | X7: =IFERROR(VLOOKUP($A$1&"-"&ROW(AJ6),基本資料填寫!$A:$DN,COLUMN(基本資料填寫!CJ7),0),"") | Y7: =IFERROR(VLOOKUP($A$1&"-"&ROW(AK6),基本資料填寫!$A:$DN,COLUMN(基本資料填寫!CK7),0),"") | Z7: =IFERROR(VLOOKUP($A$1&"-"&ROW(AM6),基本資料填寫!$A:$DN,COLUMN(基本資料填寫!CN7),0),"") | AA7: =IFERROR(VLOOKUP($A$1&"-"&ROW(AN6),基本資料填寫!$A:$DN,COLUMN(基本資料填寫!CO7),0),"") | AB7: =IFERROR(VLOOKUP($A$1&"-"&ROW(AO6),基本資料填寫!$A:$DN,COLUMN(基本資料填寫!CP7),0),"")
B8: =IF(C8="","",COUNTA($C$2:C8)) | C8: =IFERROR(VLOOKUP($A$1&"-"&ROW(C7),基本資料填寫!$A:$DN,COLUMN(基本資料填寫!S8),0),"") | D8: =IFERROR(VLOOKUP($A$1&"-"&ROW(D7),基本資料填寫!$A:$DN,COLUMN(基本資料填寫!V8),0),"") | E8: =IFERROR(VLOOKUP($A$1&"-"&ROW(E7),基本資料填寫!$A:$DN,COLUMN(基本資料填寫!BW8),0),"") | F8: =IFERROR(VLOOKUP($A$1&"-"&ROW(F7),基本資料填寫!$A:$DN,COLUMN(基本資料填寫!AN8),0),"") | G8: =IFERROR(VLOOKUP($A$1&"-"&ROW(H7),基本資料填寫!$A:$DN,COLUMN(基本資料填寫!R8),0),"") | H8: =IFERROR(VLOOKUP($A$1&"-"&ROW(X7),基本資料填寫!$A:$DN,COLUMN(基本資料填寫!BX8),0),"") | I8: =IFERROR(VLOOKUP($A$1&"-"&ROW(P7),基本資料填寫!$A:$DN,COLUMN(基本資料填寫!Z8),0),"") | J8: =IFERROR(VLOOKUP($A$1&"-"&ROW(Q7),基本資料填寫!$A:$DN,COLUMN(基本資料填寫!AA8),0),"") | K8: =IFERROR(VLOOKUP($A$1&"-"&ROW(Y7),基本資料填寫!$A:$DN,COLUMN(基本資料填寫!BY8),0),"") | L8: =IFERROR(VLOOKUP($A$1&"-"&ROW(Z7),基本資料填寫!$A:$DN,COLUMN(基本資料填寫!BZ8),0),"") | M8: =IFERROR(VLOOKUP($A$1&"-"&ROW(AA7),基本資料填寫!$A:$DN,COLUMN(基本資料填寫!CA8),0),"") | N8: =IFERROR(VLOOKUP($A$1&"-"&ROW(G7),基本資料填寫!$A:$DN,COLUMN(基本資料填寫!AO8),0),"") | O8: =IFERROR(VLOOKUP($A$1&"-"&ROW(AB7),基本資料填寫!$A:$DN,COLUMN(基本資料填寫!CB8),0),"") | P8: =IFERROR(VLOOKUP($A$1&"-"&ROW(AC7),基本資料填寫!$A:$DN,COLUMN(基本資料填寫!CC8),0),"") | Q8: =IFERROR(VLOOKUP($A$1&"-"&ROW(AD7),基本資料填寫!$A:$DN,COLUMN(基本資料填寫!CD8),0),"") | R8: =IFERROR(VLOOKUP($A$1&"-"&ROW(AE7),基本資料填寫!$A:$DN,COLUMN(基本資料填寫!CE8),0),"") | S8: =IFERROR(VLOOKUP($A$1&"-"&ROW(AF7),基本資料填寫!$A:$DN,COLUMN(基本資料填寫!CF8),0),"") | T8: =IFERROR(VLOOKUP($A$1&"-"&ROW(AG7),基本資料填寫!$A:$DN,COLUMN(基本資料填寫!CG8),0),"") | U8: =IFERROR(VLOOKUP($A$1&"-"&ROW(AH7),基本資料填寫!$A:$DN,COLUMN(基本資料填寫!CH8),0),"") | V8: =IFERROR(VLOOKUP($A$1&"-"&ROW(AI7),基本資料填寫!$A:$DN,COLUMN(基本資料填寫!CI8),0),"") | W8: =IFERROR(VLOOKUP($A$1&"-"&ROW(E7),基本資料填寫!$A:$DN,COLUMN(基本資料填寫!O8),0),"") | X8: =IFERROR(VLOOKUP($A$1&"-"&ROW(AJ7),基本資料填寫!$A:$DN,COLUMN(基本資料填寫!CJ8),0),"") | Y8: =IFERROR(VLOOKUP($A$1&"-"&ROW(AK7),基本資料填寫!$A:$DN,COLUMN(基本資料填寫!CK8),0),"") | Z8: =IFERROR(VLOOKUP($A$1&"-"&ROW(AM7),基本資料填寫!$A:$DN,COLUMN(基本資料填寫!CN8),0),"") | AA8: =IFERROR(VLOOKUP($A$1&"-"&ROW(AN7),基本資料填寫!$A:$DN,COLUMN(基本資料填寫!CO8),0),"") | AB8: =IFERROR(VLOOKUP($A$1&"-"&ROW(AO7),基本資料填寫!$A:$DN,COLUMN(基本資料填寫!CP8),0),"")
B9: =IF(C9="","",COUNTA($C$2:C9)) | C9: =IFERROR(VLOOKUP($A$1&"-"&ROW(C8),基本資料填寫!$A:$DN,COLUMN(基本資料填寫!S9),0),"") | D9: =IFERROR(VLOOKUP($A$1&"-"&ROW(D8),基本資料填寫!$A:$DN,COLUMN(基本資料填寫!V9),0),"") | E9: =IFERROR(VLOOKUP($A$1&"-"&ROW(E8),基本資料填寫!$A:$DN,COLUMN(基本資料填寫!BW9),0),"") | F9: =IFERROR(VLOOKUP($A$1&"-"&ROW(F8),基本資料填寫!$A:$DN,COLUMN(基本資料填寫!AN9),0),"") | G9: =IFERROR(VLOOKUP($A$1&"-"&ROW(H8),基本資料填寫!$A:$DN,COLUMN(基本資料填寫!R9),0),"") | H9: =IFERROR(VLOOKUP($A$1&"-"&ROW(X8),基本資料填寫!$A:$DN,COLUMN(基本資料填寫!BX9),0),"") | I9: =IFERROR(VLOOKUP($A$1&"-"&ROW(P8),基本資料填寫!$A:$DN,COLUMN(基本資料填寫!Z9),0),"") | J9: =IFERROR(VLOOKUP($A$1&"-"&ROW(Q8),基本資料填寫!$A:$DN,COLUMN(基本資料填寫!AA9),0),"") | K9: =IFERROR(VLOOKUP($A$1&"-"&ROW(Y8),基本資料填寫!$A:$DN,COLUMN(基本資料填寫!BY9),0),"") | L9: =IFERROR(VLOOKUP($A$1&"-"&ROW(Z8),基本資料填寫!$A:$DN,COLUMN(基本資料填寫!BZ9),0),"") | M9: =IFERROR(VLOOKUP($A$1&"-"&ROW(AA8),基本資料填寫!$A:$DN,COLUMN(基本資料填寫!CA9),0),"") | N9: =IFERROR(VLOOKUP($A$1&"-"&ROW(G8),基本資料填寫!$A:$DN,COLUMN(基本資料填寫!AO9),0),"") | O9: =IFERROR(VLOOKUP($A$1&"-"&ROW(AB8),基本資料填寫!$A:$DN,COLUMN(基本資料填寫!CB9),0),"") | P9: =IFERROR(VLOOKUP($A$1&"-"&ROW(AC8),基本資料填寫!$A:$DN,COLUMN(基本資料填寫!CC9),0),"") | Q9: =IFERROR(VLOOKUP($A$1&"-"&ROW(AD8),基本資料填寫!$A:$DN,COLUMN(基本資料填寫!CD9),0),"") | R9: =IFERROR(VLOOKUP($A$1&"-"&ROW(AE8),基本資料填寫!$A:$DN,COLUMN(基本資料填寫!CE9),0),"") | S9: =IFERROR(VLOOKUP($A$1&"-"&ROW(AF8),基本資料填寫!$A:$DN,COLUMN(基本資料填寫!CF9),0),"") | T9: =IFERROR(VLOOKUP($A$1&"-"&ROW(AG8),基本資料填寫!$A:$DN,COLUMN(基本資料填寫!CG9),0),"") | U9: =IFERROR(VLOOKUP($A$1&"-"&ROW(AH8),基本資料填寫!$A:$DN,COLUMN(基本資料填寫!CH9),0),"") | V9: =IFERROR(VLOOKUP($A$1&"-"&ROW(AI8),基本資料填寫!$A:$DN,COLUMN(基本資料填寫!CI9),0),"") | W9: =IFERROR(VLOOKUP($A$1&"-"&ROW(E8),基本資料填寫!$A:$DN,COLUMN(基本資料填寫!O9),0),"") | X9: =IFERROR(VLOOKUP($A$1&"-"&ROW(AJ8),基本資料填寫!$A:$DN,COLUMN(基本資料填寫!CJ9),0),"") | Y9: =IFERROR(VLOOKUP($A$1&"-"&ROW(AK8),基本資料填寫!$A:$DN,COLUMN(基本資料填寫!CK9),0),"") | Z9: =IFERROR(VLOOKUP($A$1&"-"&ROW(AM8),基本資料填寫!$A:$DN,COLUMN(基本資料填寫!CN9),0),"") | AA9: =IFERROR(VLOOKUP($A$1&"-"&ROW(AN8),基本資料填寫!$A:$DN,COLUMN(基本資料填寫!CO9),0),"") | AB9: =IFERROR(VLOOKUP($A$1&"-"&ROW(AO8),基本資料填寫!$A:$DN,COLUMN(基本資料填寫!CP9),0),"")
B10: =IF(C10="","",COUNTA($C$2:C10)) | C10: =IFERROR(VLOOKUP($A$1&"-"&ROW(C9),基本資料填寫!$A:$DN,COLUMN(基本資料填寫!S10),0),"") | D10: =IFERROR(VLOOKUP($A$1&"-"&ROW(D9),基本資料填寫!$A:$DN,COLUMN(基本資料填寫!V10),0),"") | E10: =IFERROR(VLOOKUP($A$1&"-"&ROW(E9),基本資料填寫!$A:$DN,COLUMN(基本資料填寫!BW10),0),"") | F10: =IFERROR(VLOOKUP($A$1&"-"&ROW(F9),基本資料填寫!$A:$DN,COLUMN(基本資料填寫!AN10),0),"") | G10: =IFERROR(VLOOKUP($A$1&"-"&ROW(H9),基本資料填寫!$A:$DN,COLUMN(基本資料填寫!R10),0),"") | H10: =IFERROR(VLOOKUP($A$1&"-"&ROW(X9),基本資料填寫!$A:$DN,COLUMN(基本資料填寫!BX10),0),"") | I10: =IFERROR(VLOOKUP($A$1&"-"&ROW(P9),基本資料填寫!$A:$DN,COLUMN(基本資料填寫!Z10),0),"") | J10: =IFERROR(VLOOKUP($A$1&"-"&ROW(Q9),基本資料填寫!$A:$DN,COLUMN(基本資料填寫!AA10),0),"") | K10: =IFERROR(VLOOKUP($A$1&"-"&ROW(Y9),基本資料填寫!$A:$DN,COLUMN(基本資料填寫!BY10),0),"") | L10: =IFERROR(VLOOKUP($A$1&"-"&ROW(Z9),基本資料填寫!$A:$DN,COLUMN(基本資料填寫!BZ10),0),"") | M10: =IFERROR(VLOOKUP($A$1&"-"&ROW(AA9),基本資料填寫!$A:$DN,COLUMN(基本資料填寫!CA10),0),"") | N10: =IFERROR(VLOOKUP($A$1&"-"&ROW(G9),基本資料填寫!$A:$DN,COLUMN(基本資料填寫!AO10),0),"") | O10: =IFERROR(VLOOKUP($A$1&"-"&ROW(AB9),基本資料填寫!$A:$DN,COLUMN(基本資料填寫!CB10),0),"") | P10: =IFERROR(VLOOKUP($A$1&"-"&ROW(AC9),基本資料填寫!$A:$DN,COLUMN(基本資料填寫!CC10),0),"") | Q10: =IFERROR(VLOOKUP($A$1&"-"&ROW(AD9),基本資料填寫!$A:$DN,COLUMN(基本資料填寫!CD10),0),"") | R10: =IFERROR(VLOOKUP($A$1&"-"&ROW(AE9),基本資料填寫!$A:$DN,COLUMN(基本資料填寫!CE10),0),"") | S10: =IFERROR(VLOOKUP($A$1&"-"&ROW(AF9),基本資料填寫!$A:$DN,COLUMN(基本資料填寫!CF10),0),"") | T10: =IFERROR(VLOOKUP($A$1&"-"&ROW(AG9),基本資料填寫!$A:$DN,COLUMN(基本資料填寫!CG10),0),"") | U10: =IFERROR(VLOOKUP($A$1&"-"&ROW(AH9),基本資料填寫!$A:$DN,COLUMN(基本資料填寫!CH10),0),"") | V10: =IFERROR(VLOOKUP($A$1&"-"&ROW(AI9),基本資料填寫!$A:$DN,COLUMN(基本資料填寫!CI10),0),"") | W10: =IFERROR(VLOOKUP($A$1&"-"&ROW(E9),基本資料填寫!$A:$DN,COLUMN(基本資料填寫!O10),0),"") | X10: =IFERROR(VLOOKUP($A$1&"-"&ROW(AJ9),基本資料填寫!$A:$DN,COLUMN(基本資料填寫!CJ10),0),"") | Y10: =IFERROR(VLOOKUP($A$1&"-"&ROW(AK9),基本資料填寫!$A:$DN,COLUMN(基本資料填寫!CK10),0),"") | Z10: =IFERROR(VLOOKUP($A$1&"-"&ROW(AM9),基本資料填寫!$A:$DN,COLUMN(基本資料填寫!CN10),0),"") | AA10: =IFERROR(VLOOKUP($A$1&"-"&ROW(AN9),基本資料填寫!$A:$DN,COLUMN(基本資料填寫!CO10),0),"") | AB10: =IFERROR(VLOOKUP($A$1&"-"&ROW(AO9),基本資料填寫!$A:$DN,COLUMN(基本資料填寫!CP10),0),"")
B11: =IF(C11="","",COUNTA($C$2:C11)) | C11: =IFERROR(VLOOKUP($A$1&"-"&ROW(C10),基本資料填寫!$A:$DN,COLUMN(基本資料填寫!S11),0),"") | D11: =IFERROR(VLOOKUP($A$1&"-"&ROW(D10),基本資料填寫!$A:$DN,COLUMN(基本資料填寫!V11),0),"") | E11: =IFERROR(VLOOKUP($A$1&"-"&ROW(E10),基本資料填寫!$A:$DN,COLUMN(基本資料填寫!BW11),0),"") | F11: =IFERROR(VLOOKUP($A$1&"-"&ROW(F10),基本資料填寫!$A:$DN,COLUMN(基本資料填寫!AN11),0),"") | G11: =IFERROR(VLOOKUP($A$1&"-"&ROW(H10),基本資料填寫!$A:$DN,COLUMN(基本資料填寫!R11),0),"") | H11: =IFERROR(VLOOKUP($A$1&"-"&ROW(X10),基本資料填寫!$A:$DN,COLUMN(基本資料填寫!BX11),0),"") | I11: =IFERROR(VLOOKUP($A$1&"-"&ROW(P10),基本資料填寫!$A:$DN,COLUMN(基本資料填寫!Z11),0),"") | J11: =IFERROR(VLOOKUP($A$1&"-"&ROW(Q10),基本資料填寫!$A:$DN,COLUMN(基本資料填寫!AA11),0),"") | K11: =IFERROR(VLOOKUP($A$1&"-"&ROW(Y10),基本資料填寫!$A:$DN,COLUMN(基本資料填寫!BY11),0),"") | L11: =IFERROR(VLOOKUP($A$1&"-"&ROW(Z10),基本資料填寫!$A:$DN,COLUMN(基本資料填寫!BZ11),0),"") | M11: =IFERROR(VLOOKUP($A$1&"-"&ROW(AA10),基本資料填寫!$A:$DN,COLUMN(基本資料填寫!CA11),0),"") | N11: =IFERROR(VLOOKUP($A$1&"-"&ROW(G10),基本資料填寫!$A:$DN,COLUMN(基本資料填寫!AO11),0),"") | O11: =IFERROR(VLOOKUP($A$1&"-"&ROW(AB10),基本資料填寫!$A:$DN,COLUMN(基本資料填寫!CB11),0),"") | P11: =IFERROR(VLOOKUP($A$1&"-"&ROW(AC10),基本資料填寫!$A:$DN,COLUMN(基本資料填寫!CC11),0),"") | Q11: =IFERROR(VLOOKUP($A$1&"-"&ROW(AD10),基本資料填寫!$A:$DN,COLUMN(基本資料填寫!CD11),0),"") | R11: =IFERROR(VLOOKUP($A$1&"-"&ROW(AE10),基本資料填寫!$A:$DN,COLUMN(基本資料填寫!CE11),0),"") | S11: =IFERROR(VLOOKUP($A$1&"-"&ROW(AF10),基本資料填寫!$A:$DN,COLUMN(基本資料填寫!CF11),0),"") | T11: =IFERROR(VLOOKUP($A$1&"-"&ROW(AG10),基本資料填寫!$A:$DN,COLUMN(基本資料填寫!CG11),0),"") | U11: =IFERROR(VLOOKUP($A$1&"-"&ROW(AH10),基本資料填寫!$A:$DN,COLUMN(基本資料填寫!CH11),0),"") | V11: =IFERROR(VLOOKUP($A$1&"-"&ROW(AI10),基本資料填寫!$A:$DN,COLUMN(基本資料填寫!CI11),0),"") | W11: =IFERROR(VLOOKUP($A$1&"-"&ROW(E10),基本資料填寫!$A:$DN,COLUMN(基本資料填寫!O11),0),"") | X11: =IFERROR(VLOOKUP($A$1&"-"&ROW(AJ10),基本資料填寫!$A:$DN,COLUMN(基本資料填寫!CJ11),0),"") | Y11: =IFERROR(VLOOKUP($A$1&"-"&ROW(AK10),基本資料填寫!$A:$DN,COLUMN(基本資料填寫!CK11),0),"") | Z11: =IFERROR(VLOOKUP($A$1&"-"&ROW(AM10),基本資料填寫!$A:$DN,COLUMN(基本資料填寫!CN11),0),"") | AA11: =IFERROR(VLOOKUP($A$1&"-"&ROW(AN10),基本資料填寫!$A:$DN,COLUMN(基本資料填寫!CO11),0),"") | AB11: =IFERROR(VLOOKUP($A$1&"-"&ROW(AO10),基本資料填寫!$A:$DN,COLUMN(基本資料填寫!CP11),0),"")
B12: =IF(C12="","",COUNTA($C$2:C12)) | C12: =IFERROR(VLOOKUP($A$1&"-"&ROW(C11),基本資料填寫!$A:$DN,COLUMN(基本資料填寫!S12),0),"") | D12: =IFERROR(VLOOKUP($A$1&"-"&ROW(D11),基本資料填寫!$A:$DN,COLUMN(基本資料填寫!V12),0),"") | E12: =IFERROR(VLOOKUP($A$1&"-"&ROW(E11),基本資料填寫!$A:$DN,COLUMN(基本資料填寫!BW12),0),"") | F12: =IFERROR(VLOOKUP($A$1&"-"&ROW(F11),基本資料填寫!$A:$DN,COLUMN(基本資料填寫!AN12),0),"") | G12: =IFERROR(VLOOKUP($A$1&"-"&ROW(H11),基本資料填寫!$A:$DN,COLUMN(基本資料填寫!R12),0),"") | H12: =IFERROR(VLOOKUP($A$1&"-"&ROW(X11),基本資料填寫!$A:$DN,COLUMN(基本資料填寫!BX12),0),"") | I12: =IFERROR(VLOOKUP($A$1&"-"&ROW(P11),基本資料填寫!$A:$DN,COLUMN(基本資料填寫!Z12),0),"") | J12: =IFERROR(VLOOKUP($A$1&"-"&ROW(Q11),基本資料填寫!$A:$DN,COLUMN(基本資料填寫!AA12),0),"") | K12: =IFERROR(VLOOKUP($A$1&"-"&ROW(Y11),基本資料填寫!$A:$DN,COLUMN(基本資料填寫!BY12),0),"") | L12: =IFERROR(VLOOKUP($A$1&"-"&ROW(Z11),基本資料填寫!$A:$DN,COLUMN(基本資料填寫!BZ12),0),"") | M12: =IFERROR(VLOOKUP($A$1&"-"&ROW(AA11),基本資料填寫!$A:$DN,COLUMN(基本資料填寫!CA12),0),"") | N12: =IFERROR(VLOOKUP($A$1&"-"&ROW(G11),基本資料填寫!$A:$DN,COLUMN(基本資料填寫!AO12),0),"") | O12: =IFERROR(VLOOKUP($A$1&"-"&ROW(AB11),基本資料填寫!$A:$DN,COLUMN(基本資料填寫!CB12),0),"") | P12: =IFERROR(VLOOKUP($A$1&"-"&ROW(AC11),基本資料填寫!$A:$DN,COLUMN(基本資料填寫!CC12),0),"") | Q12: =IFERROR(VLOOKUP($A$1&"-"&ROW(AD11),基本資料填寫!$A:$DN,COLUMN(基本資料填寫!CD12),0),"") | R12: =IFERROR(VLOOKUP($A$1&"-"&ROW(AE11),基本資料填寫!$A:$DN,COLUMN(基本資料填寫!CE12),0),"") | S12: =IFERROR(VLOOKUP($A$1&"-"&ROW(AF11),基本資料填寫!$A:$DN,COLUMN(基本資料填寫!CF12),0),"") | T12: =IFERROR(VLOOKUP($A$1&"-"&ROW(AG11),基本資料填寫!$A:$DN,COLUMN(基本資料填寫!CG12),0),"") | U12: =IFERROR(VLOOKUP($A$1&"-"&ROW(AH11),基本資料填寫!$A:$DN,COLUMN(基本資料填寫!CH12),0),"") | V12: =IFERROR(VLOOKUP($A$1&"-"&ROW(AI11),基本資料填寫!$A:$DN,COLUMN(基本資料填寫!CI12),0),"") | W12: =IFERROR(VLOOKUP($A$1&"-"&ROW(E11),基本資料填寫!$A:$DN,COLUMN(基本資料填寫!O12),0),"") | X12: =IFERROR(VLOOKUP($A$1&"-"&ROW(AJ11),基本資料填寫!$A:$DN,COLUMN(基本資料填寫!CJ12),0),"") | Y12: =IFERROR(VLOOKUP($A$1&"-"&ROW(AK11),基本資料填寫!$A:$DN,COLUMN(基本資料填寫!CK12),0),"") | Z12: =IFERROR(VLOOKUP($A$1&"-"&ROW(AM11),基本資料填寫!$A:$DN,COLUMN(基本資料填寫!CN12),0),"") | AA12: =IFERROR(VLOOKUP($A$1&"-"&ROW(AN11),基本資料填寫!$A:$DN,COLUMN(基本資料填寫!CO12),0),"") | AB12: =IFERROR(VLOOKUP($A$1&"-"&ROW(AO11),基本資料填寫!$A:$DN,COLUMN(基本資料填寫!CP12),0),"")
